Workbook

Sheet ALL
A1: ASSET | B1: ISIN | C1: LibelléISIN | D1: Quantité | E1: Prix de revient | F1: Place de Cotation | G1: Cours en devise | H1: Cours/VL | I1: Date du cours / VL | J1: Valorisation * | K1: "+/- Values latentes" | L1: Performance** | M1: Poids %
A2: OBLIGATION | B2: IE0000UJ3480 | C2: IS.IBD.DEC.28 T.USD UC.ETF USD IE0000UJ3480 | D2: 1 015 | E2: 98,55 € | F2: Paris | G2: 99,3746 EUR | H2: 993746 | I2: 45361 | J2: 100 865,22 € | K2: 836,97 € | L2: 0,84 % | M2: 4.4466667
A3: OBLIGATION | B3: IE000ZOI8OK5 | C3: ISHARES IBONDS DEC 2027 ¤ CORP IE000ZOI8OK5 | D3: 9 435 | E3: 5,30 € | F3: Frankfurt_ETF_ETP | G3: 5,3822 EUR | H3: 53822 | I3: 45361 | J3: 50 781,06 € | K3: 775,56 € | L3: 1,55 % | M3: 2.24
A4: OBLIGATION | B4: IE000BWITBP9 | C4: ISHRS IBD DEC 26 USD -ACC IE000BWITBP9 | D4: 2 040 | E4: 9794870 | F4: London | G4: 108,07 USD | H4: 9789836 | I4: 45361 | J4: 199 712,66 € | K4: -102,69 € | L4: -0,05 % | M4: 8.8066667
A5: OBLIGATION | B5: IE000GUOATN7 | C5: ISHS IBONDS DEC25 UC.ETF C EUR IE000GUOATN7 | D5: 19 212 | E5: 5205 | F5: Frankfurt_ETF_ETP | G5: 5,2234 EUR | H5: 52234 | I5: 45361 | J5: 100 351,96 € | K5: 353,50 € | L5: 0,35 % | M5: 4.4266667
A6: OBLIGATION | B6: IE000WA6L436 | C6: ISHS IBONDS DEC26 UC.ETF C EUR IE000WA6L436 | D6: 19 665 | E6: 52508 | F6: Paris | G6: 5,313 EUR | H6: 5313 | I6: 45361 | J6: 104 480,15 € | K6: 1 223,17 € | L6: 1,18 % | M6: 4.6066667
A7: OBLIGATION | B7: IE000I1D7D10 | C7: ISHS IBONDS DEC27 UC.ETF C USD IE000I1D7D10 | D7: 1 015 | E7: 98,70 € | F7: Paris | G7: 99,1209 EUR | H7: 991209 | I7: 45361 | J7: 100 607,71 € | K7: 427,21 € | L7: 0,43 % | M7: 4.44
A8: OBLIGATION | B8: IE0008UEVOE0 | C8: ISHS IBONDS DEC28 UC.ETF C EUR IE0008UEVOE0 | D8: 9 375 | E8: 53343 | F8: Paris | G8: 5,432 EUR | H8: 5432 | I8: 45361 | J8: 50 925,00 € | K8: 915,94 € | L8: 1,83 % | M8: 2.2466667
A9: OBLIGATION | B9: LU0115290974 | C9: ODDO BHF EUR.HIG.YLD BD CR-EUR LU0115290974 | D9: 8 319,19 | E9: 30051 | F9: OPC | G9: 30,477 EUR | H9: 30477 | I9: 45332 | J9: 253 543,95 € | K9: 3 543,97 € | L9: 1,42 % | M9: 11.186667
A10: OBLIGATION | B10: DE000A2QBG39 | C10: ODDO BHF MONEY MARKET CN-EUR DE000A2QBG39 | D10: 518363 | E10: 1 041,74000 € | F10: OPC | G10: 1048,23 EUR | H10: 1048,23 € | I10: 45332 | J10: 543 363,65 € | K10: 3 364,18 € | L10: 0,62 % | M10: 23.966667
A11: EQUITY | B11: IE00B5BMR087 | C11: ISHARES CORE S&P 500 UCITS ETF IE00B5BMR087 | D11: 1400 | E11: 53444571 | F11: Frankfurt_ETF_ETP | G11: 545,48 EUR | H11: 545,48 € | I11: 45361 | J11: 763 672,00 € | K11: 15448,00 € | L11: 2,06 % | M11: 33.333333

Sheet VIX HISTORIQUE
B1: PRODUCT | D1: DATE | E1: 2018 | F1: 6 | G1: 8 | I1: TYPE | J1: DAILY
B2: S&P | D2: IE000ZOI8OK5 | G2: CRASH | H2: -0.05 | I2: VIX THRESHOLD | J2: 25
B3: .INX | D3: VIX | G3: VIX3M | I3: VIX6M | K3: VIX1Y | N3: VIX THRESHOLD | O3: 25
A4: =IFERROR(__xludf.DUMMYFUNCTION("GOOGLEFINANCE(B$3, ""price"", DATE($E$1, $F$1, $G$1), TODAY(), $J$1)"),"Date") -> Date | B4: =IFERROR(__xludf.DUMMYFUNCTION("""COMPUTED_VALUE"""),"Close") -> Close | C4: =IFERROR(__xludf.DUMMYFUNCTION("GOOGLEFINANCE(D$3, ""price"", DATE($E$1, $F$1, $G$1), TODAY(), $J$1)"),"Date") -> Date | D4: =IFERROR(__xludf.DUMMYFUNCTION("""COMPUTED_VALUE"""),"Close") -> Close | E4: S&P Return | F4: =IFERROR(__xludf.DUMMYFUNCTION("GOOGLEFINANCE(G$3, ""price"", DATE($E$1, $F$1, $G$1), TODAY(), $J$1)"),"Date") -> Date | G4: =IFERROR(__xludf.DUMMYFUNCTION("""COMPUTED_VALUE"""),"Close") -> Close | H4: =IFERROR(__xludf.DUMMYFUNCTION("GOOGLEFINANCE(I$3, ""price"", DATE($E$1, $F$1, $G$1), TODAY(), $J$1)"),"Date") -> Date | I4: =IFERROR(__xludf.DUMMYFUNCTION("""COMPUTED_VALUE"""),"Close") -> Close | J4: =IFERROR(__xludf.DUMMYFUNCTION("GOOGLEFINANCE(K$3, ""price"", DATE($E$1, $F$1, $G$1), TODAY(), $J$1)"),"Date") -> Date | K4: =IFERROR(__xludf.DUMMYFUNCTION("""COMPUTED_VALUE"""),"Close") -> Close | M4: CRAH TEST | N4: PREDICT CRASH
A5: =IFERROR(__xludf.DUMMYFUNCTION("""COMPUTED_VALUE"""),43259.66666666667) -> 43259.667 | B5: =IFERROR(__xludf.DUMMYFUNCTION("""COMPUTED_VALUE"""),2779.03) -> 2779.03 | C5: =IFERROR(__xludf.DUMMYFUNCTION("""COMPUTED_VALUE"""),43259.63611111111) -> 43259.636 | D5: =IFERROR(__xludf.DUMMYFUNCTION("""COMPUTED_VALUE"""),12.18) -> 12.18 | F5: =IFERROR(__xludf.DUMMYFUNCTION("""COMPUTED_VALUE"""),43259.63611111111) -> 43259.636 | G5: =IFERROR(__xludf.DUMMYFUNCTION("""COMPUTED_VALUE"""),14.6) -> 14.6 | H5: =IFERROR(__xludf.DUMMYFUNCTION("""COMPUTED_VALUE"""),43259.63611111111) -> 43259.636 | I5: =IFERROR(__xludf.DUMMYFUNCTION("""COMPUTED_VALUE"""),16.13) -> 16.13 | J5: =IFERROR(__xludf.DUMMYFUNCTION("""COMPUTED_VALUE"""),43259.63611111111) -> 43259.636 | K5: =IFERROR(__xludf.DUMMYFUNCTION("""COMPUTED_VALUE"""),17.23) -> 17.23 | N5: =IF(I5>$O$3,"PREDICT CRASH","") | O5: =IF(E5>$O$3,"PREDICT CRASH","")
A6: =IFERROR(__xludf.DUMMYFUNCTION("""COMPUTED_VALUE"""),43262.66666666667) -> 43262.667 | B6: =IFERROR(__xludf.DUMMYFUNCTION("""COMPUTED_VALUE"""),2782.0) -> 2782 | C6: =IFERROR(__xludf.DUMMYFUNCTION("""COMPUTED_VALUE"""),43262.63611111111) -> 43262.636 | D6: =IFERROR(__xludf.DUMMYFUNCTION("""COMPUTED_VALUE"""),12.35) -> 12.35 | E6: =B6/B5-1 -> 0.0010687182 | F6: =IFERROR(__xludf.DUMMYFUNCTION("""COMPUTED_VALUE"""),43262.63611111111) -> 43262.636 | G6: =IFERROR(__xludf.DUMMYFUNCTION("""COMPUTED_VALUE"""),14.55) -> 14.55 | H6: =IFERROR(__xludf.DUMMYFUNCTION("""COMPUTED_VALUE"""),43262.63611111111) -> 43262.636 | I6: =IFERROR(__xludf.DUMMYFUNCTION("""COMPUTED_VALUE"""),16.12) -> 16.12 | J6: =IFERROR(__xludf.DUMMYFUNCTION("""COMPUTED_VALUE"""),43262.63611111111) -> 43262.636 | K6: =IFERROR(__xludf.DUMMYFUNCTION("""COMPUTED_VALUE"""),17.17) -> 17.17 | M6: =If((E6<$H$2),"CRASH","") | N6: =IF(I6>$O$3,"PREDICT CRASH","")
A7: =IFERROR(__xludf.DUMMYFUNCTION("""COMPUTED_VALUE"""),43263.66666666667) -> 43263.667 | B7: =IFERROR(__xludf.DUMMYFUNCTION("""COMPUTED_VALUE"""),2786.85) -> 2786.85 | C7: =IFERROR(__xludf.DUMMYFUNCTION("""COMPUTED_VALUE"""),43263.63611111111) -> 43263.636 | D7: =IFERROR(__xludf.DUMMYFUNCTION("""COMPUTED_VALUE"""),12.34) -> 12.34 | E7: =B7/B6-1 -> 0.0017433501 | F7: =IFERROR(__xludf.DUMMYFUNCTION("""COMPUTED_VALUE"""),43263.63611111111) -> 43263.636 | G7: =IFERROR(__xludf.DUMMYFUNCTION("""COMPUTED_VALUE"""),14.59) -> 14.59 | H7: =IFERROR(__xludf.DUMMYFUNCTION("""COMPUTED_VALUE"""),43263.63611111111) -> 43263.636 | I7: =IFERROR(__xludf.DUMMYFUNCTION("""COMPUTED_VALUE"""),16.17) -> 16.17 | J7: =IFERROR(__xludf.DUMMYFUNCTION("""COMPUTED_VALUE"""),43263.63611111111) -> 43263.636 | K7: =IFERROR(__xludf.DUMMYFUNCTION("""COMPUTED_VALUE"""),17.23) -> 17.23 | M7: =If((E7<$H$2),"CRASH","") | N7: =IF(I7>$O$3,"PREDICT CRASH","")
A8: =IFERROR(__xludf.DUMMYFUNCTION("""COMPUTED_VALUE"""),43264.66666666667) -> 43264.667 | B8: =IFERROR(__xludf.DUMMYFUNCTION("""COMPUTED_VALUE"""),2775.63) -> 2775.63 | C8: =IFERROR(__xludf.DUMMYFUNCTION("""COMPUTED_VALUE"""),43264.63611111111) -> 43264.636 | D8: =IFERROR(__xludf.DUMMYFUNCTION("""COMPUTED_VALUE"""),12.94) -> 12.94 | E8: =B8/B7-1 -> -0.0040260509 | F8: =IFERROR(__xludf.DUMMYFUNCTION("""COMPUTED_VALUE"""),43264.63611111111) -> 43264.636 | G8: =IFERROR(__xludf.DUMMYFUNCTION("""COMPUTED_VALUE"""),14.92) -> 14.92 | H8: =IFERROR(__xludf.DUMMYFUNCTION("""COMPUTED_VALUE"""),43264.63611111111) -> 43264.636 | I8: =IFERROR(__xludf.DUMMYFUNCTION("""COMPUTED_VALUE"""),16.43) -> 16.43 | J8: =IFERROR(__xludf.DUMMYFUNCTION("""COMPUTED_VALUE"""),43264.63611111111) -> 43264.636 | K8: =IFERROR(__xludf.DUMMYFUNCTION("""COMPUTED_VALUE"""),17.44) -> 17.44 | M8: =If((E8<$H$2),"CRASH","") | N8: =IF(I8>$O$3,"PREDICT CRASH","")
A9: =IFERROR(__xludf.DUMMYFUNCTION("""COMPUTED_VALUE"""),43265.66666666667) -> 43265.667 | B9: =IFERROR(__xludf.DUMMYFUNCTION("""COMPUTED_VALUE"""),2782.49) -> 2782.49 | C9: =IFERROR(__xludf.DUMMYFUNCTION("""COMPUTED_VALUE"""),43265.63611111111) -> 43265.636 | D9: =IFERROR(__xludf.DUMMYFUNCTION("""COMPUTED_VALUE"""),12.12) -> 12.12 | E9: =B9/B8-1 -> 0.002471511 | F9: =IFERROR(__xludf.DUMMYFUNCTION("""COMPUTED_VALUE"""),43265.63611111111) -> 43265.636 | G9: =IFERROR(__xludf.DUMMYFUNCTION("""COMPUTED_VALUE"""),14.4) -> 14.4 | H9: =IFERROR(__xludf.DUMMYFUNCTION("""COMPUTED_VALUE"""),43265.63611111111) -> 43265.636 | I9: =IFERROR(__xludf.DUMMYFUNCTION("""COMPUTED_VALUE"""),16.09) -> 16.09 | J9: =IFERROR(__xludf.DUMMYFUNCTION("""COMPUTED_VALUE"""),43265.63611111111) -> 43265.636 | K9: =IFERROR(__xludf.DUMMYFUNCTION("""COMPUTED_VALUE"""),17.31) -> 17.31 | M9: =If((E9<$H$2),"CRASH","") | N9: =IF(I9>$O$3,"PREDICT CRASH","")
A10: =IFERROR(__xludf.DUMMYFUNCTION("""COMPUTED_VALUE"""),43266.66666666667) -> 43266.667 | B10: =IFERROR(__xludf.DUMMYFUNCTION("""COMPUTED_VALUE"""),2779.66) -> 2779.66 | C10: =IFERROR(__xludf.DUMMYFUNCTION("""COMPUTED_VALUE"""),43266.63611111111) -> 43266.636 | D10: =IFERROR(__xludf.DUMMYFUNCTION("""COMPUTED_VALUE"""),11.98) -> 11.98 | E10: =B10/B9-1 -> -0.0010170746 | F10: =IFERROR(__xludf.DUMMYFUNCTION("""COMPUTED_VALUE"""),43266.63611111111) -> 43266.636 | G10: =IFERROR(__xludf.DUMMYFUNCTION("""COMPUTED_VALUE"""),14.42) -> 14.42 | H10: =IFERROR(__xludf.DUMMYFUNCTION("""COMPUTED_VALUE"""),43266.63611111111) -> 43266.636 | I10: =IFERROR(__xludf.DUMMYFUNCTION("""COMPUTED_VALUE"""),16.32) -> 16.32 | J10: =IFERROR(__xludf.DUMMYFUNCTION("""COMPUTED_VALUE"""),43266.63611111111) -> 43266.636 | K10: =IFERROR(__xludf.DUMMYFUNCTION("""COMPUTED_VALUE"""),17.54) -> 17.54 | M10: =If((E10<$H$2),"CRASH","") | N10: =IF(I10>$O$3,"PREDICT CRASH","")
A11: =IFERROR(__xludf.DUMMYFUNCTION("""COMPUTED_VALUE"""),43269.66666666667) -> 43269.667 | B11: =IFERROR(__xludf.DUMMYFUNCTION("""COMPUTED_VALUE"""),2773.75) -> 2773.75 | C11: =IFERROR(__xludf.DUMMYFUNCTION("""COMPUTED_VALUE"""),43269.63611111111) -> 43269.636 | D11: =IFERROR(__xludf.DUMMYFUNCTION("""COMPUTED_VALUE"""),12.31) -> 12.31 | E11: =B11/B10-1 -> -0.0021261593 | F11: =IFERROR(__xludf.DUMMYFUNCTION("""COMPUTED_VALUE"""),43269.63611111111) -> 43269.636 | G11: =IFERROR(__xludf.DUMMYFUNCTION("""COMPUTED_VALUE"""),14.48) -> 14.48 | H11: =IFERROR(__xludf.DUMMYFUNCTION("""COMPUTED_VALUE"""),43269.63611111111) -> 43269.636 | I11: =IFERROR(__xludf.DUMMYFUNCTION("""COMPUTED_VALUE"""),16.35) -> 16.35 | J11: =IFERROR(__xludf.DUMMYFUNCTION("""COMPUTED_VALUE"""),43269.63611111111) -> 43269.636 | K11: =IFERROR(__xludf.DUMMYFUNCTION("""COMPUTED_VALUE"""),17.61) -> 17.61 | M11: =If((E11<$H$2),"CRASH","") | N11: =IF(I11>$O$3,"PREDICT CRASH","")
A12: =IFERROR(__xludf.DUMMYFUNCTION("""COMPUTED_VALUE"""),43270.66666666667) -> 43270.667 | B12: =IFERROR(__xludf.DUMMYFUNCTION("""COMPUTED_VALUE"""),2762.59) -> 2762.59 | C12: =IFERROR(__xludf.DUMMYFUNCTION("""COMPUTED_VALUE"""),43270.63611111111) -> 43270.636 | D12: =IFERROR(__xludf.DUMMYFUNCTION("""COMPUTED_VALUE"""),13.35) -> 13.35 | E12: =B12/B11-1 -> -0.004023434 | F12: =IFERROR(__xludf.DUMMYFUNCTION("""COMPUTED_VALUE"""),43270.63611111111) -> 43270.636 | G12: =IFERROR(__xludf.DUMMYFUNCTION("""COMPUTED_VALUE"""),15.17) -> 15.17 | H12: =IFERROR(__xludf.DUMMYFUNCTION("""COMPUTED_VALUE"""),43270.63611111111) -> 43270.636 | I12: =IFERROR(__xludf.DUMMYFUNCTION("""COMPUTED_VALUE"""),16.89) -> 16.89 | J12: =IFERROR(__xludf.DUMMYFUNCTION("""COMPUTED_VALUE"""),43270.63611111111) -> 43270.636 | K12: =IFERROR(__xludf.DUMMYFUNCTION("""COMPUTED_VALUE"""),18.09) -> 18.09 | M12: =If((E12<$H$2),"CRASH","") | N12: =IF(I12>$O$3,"PREDICT CRASH","")
A13: =IFERROR(__xludf.DUMMYFUNCTION("""COMPUTED_VALUE"""),43271.66666666667) -> 43271.667 | B13: =IFERROR(__xludf.DUMMYFUNCTION("""COMPUTED_VALUE"""),2767.32) -> 2767.32 | C13: =IFERROR(__xludf.DUMMYFUNCTION("""COMPUTED_VALUE"""),43271.63611111111) -> 43271.636 | D13: =IFERROR(__xludf.DUMMYFUNCTION("""COMPUTED_VALUE"""),12.79) -> 12.79 | E13: =B13/B12-1 -> 0.0017121614 | F13: =IFERROR(__xludf.DUMMYFUNCTION("""COMPUTED_VALUE"""),43271.63611111111) -> 43271.636 | G13: =IFERROR(__xludf.DUMMYFUNCTION("""COMPUTED_VALUE"""),14.79) -> 14.79 | H13: =IFERROR(__xludf.DUMMYFUNCTION("""COMPUTED_VALUE"""),43271.63611111111) -> 43271.636 | I13: =IFERROR(__xludf.DUMMYFUNCTION("""COMPUTED_VALUE"""),16.52) -> 16.52 | J13: =IFERROR(__xludf.DUMMYFUNCTION("""COMPUTED_VALUE"""),43271.63611111111) -> 43271.636 | K13: =IFERROR(__xludf.DUMMYFUNCTION("""COMPUTED_VALUE"""),17.77) -> 17.77 | M13: =If((E13<$H$2),"CRASH","") | N13: =IF(I13>$O$3,"PREDICT CRASH","")
A14: =IFERROR(__xludf.DUMMYFUNCTION("""COMPUTED_VALUE"""),43272.66666666667) -> 43272.667 | B14: =IFERROR(__xludf.DUMMYFUNCTION("""COMPUTED_VALUE"""),2749.76) -> 2749.76 | C14: =IFERROR(__xludf.DUMMYFUNCTION("""COMPUTED_VALUE"""),43272.63611111111) -> 43272.636 | D14: =IFERROR(__xludf.DUMMYFUNCTION("""COMPUTED_VALUE"""),14.64) -> 14.64 | E14: =B14/B13-1 -> -0.0063454895 | F14: =IFERROR(__xludf.DUMMYFUNCTION("""COMPUTED_VALUE"""),43272.63611111111) -> 43272.636 | G14: =IFERROR(__xludf.DUMMYFUNCTION("""COMPUTED_VALUE"""),15.87) -> 15.87 | H14: =IFERROR(__xludf.DUMMYFUNCTION("""COMPUTED_VALUE"""),43272.63611111111) -> 43272.636 | I14: =IFERROR(__xludf.DUMMYFUNCTION("""COMPUTED_VALUE"""),17.2) -> 17.2 | J14: =IFERROR(__xludf.DUMMYFUNCTION("""COMPUTED_VALUE"""),43272.63611111111) -> 43272.636 | K14: =IFERROR(__xludf.DUMMYFUNCTION("""COMPUTED_VALUE"""),18.18) -> 18.18 | M14: =If((E14<$H$2),"CRASH","") | N14: =IF(I14>$O$3,"PREDICT CRASH","")
A15: =IFERROR(__xludf.DUMMYFUNCTION("""COMPUTED_VALUE"""),43273.66666666667) -> 43273.667 | B15: =IFERROR(__xludf.DUMMYFUNCTION("""COMPUTED_VALUE"""),2754.88) -> 2754.88 | C15: =IFERROR(__xludf.DUMMYFUNCTION("""COMPUTED_VALUE"""),43273.63611111111) -> 43273.636 | D15: =IFERROR(__xludf.DUMMYFUNCTION("""COMPUTED_VALUE"""),13.77) -> 13.77 | E15: =B15/B14-1 -> 0.0018619807 | F15: =IFERROR(__xludf.DUMMYFUNCTION("""COMPUTED_VALUE"""),43273.63611111111) -> 43273.636 | G15: =IFERROR(__xludf.DUMMYFUNCTION("""COMPUTED_VALUE"""),15.5) -> 15.5 | H15: =IFERROR(__xludf.DUMMYFUNCTION("""COMPUTED_VALUE"""),43273.63611111111) -> 43273.636 | I15: =IFERROR(__xludf.DUMMYFUNCTION("""COMPUTED_VALUE"""),16.92) -> 16.92 | J15: =IFERROR(__xludf.DUMMYFUNCTION("""COMPUTED_VALUE"""),43273.63611111111) -> 43273.636 | K15: =IFERROR(__xludf.DUMMYFUNCTION("""COMPUTED_VALUE"""),18.12) -> 18.12 | M15: =If((E15<$H$2),"CRASH","") | N15: =IF(I15>$O$3,"PREDICT CRASH","")
A16: =IFERROR(__xludf.DUMMYFUNCTION("""COMPUTED_VALUE"""),43276.66666666667) -> 43276.667 | B16: =IFERROR(__xludf.DUMMYFUNCTION("""COMPUTED_VALUE"""),2717.07) -> 2717.07 | C16: =IFERROR(__xludf.DUMMYFUNCTION("""COMPUTED_VALUE"""),43276.63611111111) -> 43276.636 | D16: =IFERROR(__xludf.DUMMYFUNCTION("""COMPUTED_VALUE"""),17.33) -> 17.33 | E16: =B16/B15-1 -> -0.013724736 | F16: =IFERROR(__xludf.DUMMYFUNCTION("""COMPUTED_VALUE"""),43276.63611111111) -> 43276.636 | G16: =IFERROR(__xludf.DUMMYFUNCTION("""COMPUTED_VALUE"""),17.52) -> 17.52 | H16: =IFERROR(__xludf.DUMMYFUNCTION("""COMPUTED_VALUE"""),43276.63611111111) -> 43276.636 | I16: =IFERROR(__xludf.DUMMYFUNCTION("""COMPUTED_VALUE"""),18.27) -> 18.27 | J16: =IFERROR(__xludf.DUMMYFUNCTION("""COMPUTED_VALUE"""),43276.63611111111) -> 43276.636 | K16: =IFERROR(__xludf.DUMMYFUNCTION("""COMPUTED_VALUE"""),18.87) -> 18.87 | M16: =If((E16<$H$2),"CRASH","") | N16: =IF(I16>$O$3,"PREDICT CRASH","")
A17: =IFERROR(__xludf.DUMMYFUNCTION("""COMPUTED_VALUE"""),43277.66666666667) -> 43277.667 | B17: =IFERROR(__xludf.DUMMYFUNCTION("""COMPUTED_VALUE"""),2723.06) -> 2723.06 | C17: =IFERROR(__xludf.DUMMYFUNCTION("""COMPUTED_VALUE"""),43277.63611111111) -> 43277.636 | D17: =IFERROR(__xludf.DUMMYFUNCTION("""COMPUTED_VALUE"""),15.92) -> 15.92 | E17: =B17/B16-1 -> 0.0022045807 | F17: =IFERROR(__xludf.DUMMYFUNCTION("""COMPUTED_VALUE"""),43277.63611111111) -> 43277.636 | G17: =IFERROR(__xludf.DUMMYFUNCTION("""COMPUTED_VALUE"""),16.87) -> 16.87 | H17: =IFERROR(__xludf.DUMMYFUNCTION("""COMPUTED_VALUE"""),43277.63611111111) -> 43277.636 | I17: =IFERROR(__xludf.DUMMYFUNCTION("""COMPUTED_VALUE"""),17.79) -> 17.79 | J17: =IFERROR(__xludf.DUMMYFUNCTION("""COMPUTED_VALUE"""),43277.63611111111) -> 43277.636 | K17: =IFERROR(__xludf.DUMMYFUNCTION("""COMPUTED_VALUE"""),18.49) -> 18.49 | M17: =If((E17<$H$2),"CRASH","") | N17: =IF(I17>$O$3,"PREDICT CRASH","")
A18: =IFERROR(__xludf.DUMMYFUNCTION("""COMPUTED_VALUE"""),43278.66666666667) -> 43278.667 | B18: =IFERROR(__xludf.DUMMYFUNCTION("""COMPUTED_VALUE"""),2699.63) -> 2699.63 | C18: =IFERROR(__xludf.DUMMYFUNCTION("""COMPUTED_VALUE"""),43278.63611111111) -> 43278.636 | D18: =IFERROR(__xludf.DUMMYFUNCTION("""COMPUTED_VALUE"""),17.91) -> 17.91 | E18: =B18/B17-1 -> -0.0086042908 | F18: =IFERROR(__xludf.DUMMYFUNCTION("""COMPUTED_VALUE"""),43278.63611111111) -> 43278.636 | G18: =IFERROR(__xludf.DUMMYFUNCTION("""COMPUTED_VALUE"""),18.05) -> 18.05 | H18: =IFERROR(__xludf.DUMMYFUNCTION("""COMPUTED_VALUE"""),43278.63611111111) -> 43278.636 | I18: =IFERROR(__xludf.DUMMYFUNCTION("""COMPUTED_VALUE"""),18.66) -> 18.66 | J18: =IFERROR(__xludf.DUMMYFUNCTION("""COMPUTED_VALUE"""),43278.63611111111) -> 43278.636 | K18: =IFERROR(__xludf.DUMMYFUNCTION("""COMPUTED_VALUE"""),18.99) -> 18.99 | M18: =If((E18<$H$2),"CRASH","") | N18: =IF(I18>$O$3,"PREDICT CRASH","")
A19: =IFERROR(__xludf.DUMMYFUNCTION("""COMPUTED_VALUE"""),43279.66666666667) -> 43279.667 | B19: =IFERROR(__xludf.DUMMYFUNCTION("""COMPUTED_VALUE"""),2716.31) -> 2716.31 | C19: =IFERROR(__xludf.DUMMYFUNCTION("""COMPUTED_VALUE"""),43279.63611111111) -> 43279.636 | D19: =IFERROR(__xludf.DUMMYFUNCTION("""COMPUTED_VALUE"""),16.85) -> 16.85 | E19: =B19/B18-1 -> 0.0061786245 | F19: =IFERROR(__xludf.DUMMYFUNCTION("""COMPUTED_VALUE"""),43279.63611111111) -> 43279.636 | G19: =IFERROR(__xludf.DUMMYFUNCTION("""COMPUTED_VALUE"""),17.52) -> 17.52 | H19: =IFERROR(__xludf.DUMMYFUNCTION("""COMPUTED_VALUE"""),43279.63611111111) -> 43279.636 | I19: =IFERROR(__xludf.DUMMYFUNCTION("""COMPUTED_VALUE"""),18.29) -> 18.29 | J19: =IFERROR(__xludf.DUMMYFUNCTION("""COMPUTED_VALUE"""),43279.63611111111) -> 43279.636 | K19: =IFERROR(__xludf.DUMMYFUNCTION("""COMPUTED_VALUE"""),18.78) -> 18.78 | M19: =If((E19<$H$2),"CRASH","") | N19: =IF(I19>$O$3,"PREDICT CRASH","")
A20: =IFERROR(__xludf.DUMMYFUNCTION("""COMPUTED_VALUE"""),43280.66666666667) -> 43280.667 | B20: =IFERROR(__xludf.DUMMYFUNCTION("""COMPUTED_VALUE"""),2718.37) -> 2718.37 | C20: =IFERROR(__xludf.DUMMYFUNCTION("""COMPUTED_VALUE"""),43280.63611111111) -> 43280.636 | D20: =IFERROR(__xludf.DUMMYFUNCTION("""COMPUTED_VALUE"""),16.09) -> 16.09 | E20: =B20/B19-1 -> 0.00075838178 | F20: =IFERROR(__xludf.DUMMYFUNCTION("""COMPUTED_VALUE"""),43280.63611111111) -> 43280.636 | G20: =IFERROR(__xludf.DUMMYFUNCTION("""COMPUTED_VALUE"""),17.14) -> 17.14 | H20: =IFERROR(__xludf.DUMMYFUNCTION("""COMPUTED_VALUE"""),43280.63611111111) -> 43280.636 | I20: =IFERROR(__xludf.DUMMYFUNCTION("""COMPUTED_VALUE"""),18.09) -> 18.09 | J20: =IFERROR(__xludf.DUMMYFUNCTION("""COMPUTED_VALUE"""),43280.63611111111) -> 43280.636 | K20: =IFERROR(__xludf.DUMMYFUNCTION("""COMPUTED_VALUE"""),18.67) -> 18.67 | M20: =If((E20<$H$2),"CRASH","") | N20: =IF(I20>$O$3,"PREDICT CRASH","")
A21: =IFERROR(__xludf.DUMMYFUNCTION("""COMPUTED_VALUE"""),43283.66666666667) -> 43283.667 | B21: =IFERROR(__xludf.DUMMYFUNCTION("""COMPUTED_VALUE"""),2726.71) -> 2726.71 | C21: =IFERROR(__xludf.DUMMYFUNCTION("""COMPUTED_VALUE"""),43283.63611111111) -> 43283.636 | D21: =IFERROR(__xludf.DUMMYFUNCTION("""COMPUTED_VALUE"""),15.6) -> 15.6 | E21: =B21/B20-1 -> 0.003068015 | F21: =IFERROR(__xludf.DUMMYFUNCTION("""COMPUTED_VALUE"""),43283.63611111111) -> 43283.636 | G21: =IFERROR(__xludf.DUMMYFUNCTION("""COMPUTED_VALUE"""),16.95) -> 16.95 | H21: =IFERROR(__xludf.DUMMYFUNCTION("""COMPUTED_VALUE"""),43283.63611111111) -> 43283.636 | I21: =IFERROR(__xludf.DUMMYFUNCTION("""COMPUTED_VALUE"""),17.97) -> 17.97 | J21: =IFERROR(__xludf.DUMMYFUNCTION("""COMPUTED_VALUE"""),43283.63611111111) -> 43283.636 | K21: =IFERROR(__xludf.DUMMYFUNCTION("""COMPUTED_VALUE"""),18.65) -> 18.65 | M21: =If((E21<$H$2),"CRASH","") | N21: =IF(I21>$O$3,"PREDICT CRASH","")
A22: =IFERROR(__xludf.DUMMYFUNCTION("""COMPUTED_VALUE"""),43284.54166666667) -> 43284.542 | B22: =IFERROR(__xludf.DUMMYFUNCTION("""COMPUTED_VALUE"""),2713.22) -> 2713.22 | C22: =IFERROR(__xludf.DUMMYFUNCTION("""COMPUTED_VALUE"""),43284.54166666667) -> 43284.542 | D22: =IFERROR(__xludf.DUMMYFUNCTION("""COMPUTED_VALUE"""),16.14) -> 16.14 | E22: =B22/B21-1 -> -0.0049473541 | F22: =IFERROR(__xludf.DUMMYFUNCTION("""COMPUTED_VALUE"""),43284.54166666667) -> 43284.542 | G22: =IFERROR(__xludf.DUMMYFUNCTION("""COMPUTED_VALUE"""),17.35) -> 17.35 | H22: =IFERROR(__xludf.DUMMYFUNCTION("""COMPUTED_VALUE"""),43284.54166666667) -> 43284.542 | I22: =IFERROR(__xludf.DUMMYFUNCTION("""COMPUTED_VALUE"""),18.23) -> 18.23 | J22: =IFERROR(__xludf.DUMMYFUNCTION("""COMPUTED_VALUE"""),43284.54166666667) -> 43284.542 | K22: =IFERROR(__xludf.DUMMYFUNCTION("""COMPUTED_VALUE"""),18.82) -> 18.82 | M22: =If((E22<$H$2),"CRASH","") | N22: =IF(I22>$O$3,"PREDICT CRASH","")
A23: =IFERROR(__xludf.DUMMYFUNCTION("""COMPUTED_VALUE"""),43286.66666666667) -> 43286.667 | B23: =IFERROR(__xludf.DUMMYFUNCTION("""COMPUTED_VALUE"""),2736.61) -> 2736.61 | C23: =IFERROR(__xludf.DUMMYFUNCTION("""COMPUTED_VALUE"""),43286.63611111111) -> 43286.636 | D23: =IFERROR(__xludf.DUMMYFUNCTION("""COMPUTED_VALUE"""),14.97) -> 14.97 | E23: =B23/B22-1 -> 0.0086207532 | F23: =IFERROR(__xludf.DUMMYFUNCTION("""COMPUTED_VALUE"""),43286.63611111111) -> 43286.636 | G23: =IFERROR(__xludf.DUMMYFUNCTION("""COMPUTED_VALUE"""),16.53) -> 16.53 | H23: =IFERROR(__xludf.DUMMYFUNCTION("""COMPUTED_VALUE"""),43286.63611111111) -> 43286.636 | I23: =IFERROR(__xludf.DUMMYFUNCTION("""COMPUTED_VALUE"""),17.63) -> 17.63 | J23: =IFERROR(__xludf.DUMMYFUNCTION("""COMPUTED_VALUE"""),43286.63611111111) -> 43286.636 | K23: =IFERROR(__xludf.DUMMYFUNCTION("""COMPUTED_VALUE"""),18.35) -> 18.35 | M23: =If((E23<$H$2),"CRASH","") | N23: =IF(I23>$O$3,"PREDICT CRASH","")
A24: =IFERROR(__xludf.DUMMYFUNCTION("""COMPUTED_VALUE"""),43287.66666666667) -> 43287.667 | B24: =IFERROR(__xludf.DUMMYFUNCTION("""COMPUTED_VALUE"""),2759.82) -> 2759.82 | C24: =IFERROR(__xludf.DUMMYFUNCTION("""COMPUTED_VALUE"""),43287.63611111111) -> 43287.636 | D24: =IFERROR(__xludf.DUMMYFUNCTION("""COMPUTED_VALUE"""),13.37) -> 13.37 | E24: =B24/B23-1 -> 0.0084812962 | F24: =IFERROR(__xludf.DUMMYFUNCTION("""COMPUTED_VALUE"""),43287.63611111111) -> 43287.636 | G24: =IFERROR(__xludf.DUMMYFUNCTION("""COMPUTED_VALUE"""),15.71) -> 15.71 | H24: =IFERROR(__xludf.DUMMYFUNCTION("""COMPUTED_VALUE"""),43287.63611111111) -> 43287.636 | I24: =IFERROR(__xludf.DUMMYFUNCTION("""COMPUTED_VALUE"""),17.07) -> 17.07 | J24: =IFERROR(__xludf.DUMMYFUNCTION("""COMPUTED_VALUE"""),43287.63611111111) -> 43287.636 | K24: =IFERROR(__xludf.DUMMYFUNCTION("""COMPUTED_VALUE"""),18.0) -> 18 | M24: =If((E24<$H$2),"CRASH","") | N24: =IF(I24>$O$3,"PREDICT CRASH","")
A25: =IFERROR(__xludf.DUMMYFUNCTION("""COMPUTED_VALUE"""),43290.66666666667) -> 43290.667 | B25: =IFERROR(__xludf.DUMMYFUNCTION("""COMPUTED_VALUE"""),2784.17) -> 2784.17 | C25: =IFERROR(__xludf.DUMMYFUNCTION("""COMPUTED_VALUE"""),43290.63611111111) -> 43290.636 | D25: =IFERROR(__xludf.DUMMYFUNCTION("""COMPUTED_VALUE"""),12.69) -> 12.69 | E25: =B25/B24-1 -> 0.0088230392 | F25: =IFERROR(__xludf.DUMMYFUNCTION("""COMPUTED_VALUE"""),43290.63611111111) -> 43290.636 | G25: =IFERROR(__xludf.DUMMYFUNCTION("""COMPUTED_VALUE"""),14.87) -> 14.87 | H25: =IFERROR(__xludf.DUMMYFUNCTION("""COMPUTED_VALUE"""),43290.63611111111) -> 43290.636 | I25: =IFERROR(__xludf.DUMMYFUNCTION("""COMPUTED_VALUE"""),16.29) -> 16.29 | J25: =IFERROR(__xludf.DUMMYFUNCTION("""COMPUTED_VALUE"""),43290.63611111111) -> 43290.636 | K25: =IFERROR(__xludf.DUMMYFUNCTION("""COMPUTED_VALUE"""),17.4) -> 17.4 | M25: =If((E25<$H$2),"CRASH","") | N25: =IF(I25>$O$3,"PREDICT CRASH","")
A26: =IFERROR(__xludf.DUMMYFUNCTION("""COMPUTED_VALUE"""),43291.66666666667) -> 43291.667 | B26: =IFERROR(__xludf.DUMMYFUNCTION("""COMPUTED_VALUE"""),2793.84) -> 2793.84 | C26: =IFERROR(__xludf.DUMMYFUNCTION("""COMPUTED_VALUE"""),43291.63611111111) -> 43291.636 | D26: =IFERROR(__xludf.DUMMYFUNCTION("""COMPUTED_VALUE"""),12.64) -> 12.64 | E26: =B26/B25-1 -> 0.0034732075 | F26: =IFERROR(__xludf.DUMMYFUNCTION("""COMPUTED_VALUE"""),43291.63611111111) -> 43291.636 | G26: =IFERROR(__xludf.DUMMYFUNCTION("""COMPUTED_VALUE"""),14.71) -> 14.71 | H26: =IFERROR(__xludf.DUMMYFUNCTION("""COMPUTED_VALUE"""),43291.63611111111) -> 43291.636 | I26: =IFERROR(__xludf.DUMMYFUNCTION("""COMPUTED_VALUE"""),16.11) -> 16.11 | J26: =IFERROR(__xludf.DUMMYFUNCTION("""COMPUTED_VALUE"""),43291.63611111111) -> 43291.636 | K26: =IFERROR(__xludf.DUMMYFUNCTION("""COMPUTED_VALUE"""),17.23) -> 17.23 | M26: =If((E26<$H$2),"CRASH","") | N26: =IF(I26>$O$3,"PREDICT CRASH","")
A27: =IFERROR(__xludf.DUMMYFUNCTION("""COMPUTED_VALUE"""),43292.66666666667) -> 43292.667 | B27: =IFERROR(__xludf.DUMMYFUNCTION("""COMPUTED_VALUE"""),2774.02) -> 2774.02 | C27: =IFERROR(__xludf.DUMMYFUNCTION("""COMPUTED_VALUE"""),43292.63611111111) -> 43292.636 | D27: =IFERROR(__xludf.DUMMYFUNCTION("""COMPUTED_VALUE"""),13.63) -> 13.63 | E27: =B27/B26-1 -> -0.0070941786 | F27: =IFERROR(__xludf.DUMMYFUNCTION("""COMPUTED_VALUE"""),43292.63611111111) -> 43292.636 | G27: =IFERROR(__xludf.DUMMYFUNCTION("""COMPUTED_VALUE"""),15.38) -> 15.38 | H27: =IFERROR(__xludf.DUMMYFUNCTION("""COMPUTED_VALUE"""),43292.63611111111) -> 43292.636 | I27: =IFERROR(__xludf.DUMMYFUNCTION("""COMPUTED_VALUE"""),16.54) -> 16.54 | J27: =IFERROR(__xludf.DUMMYFUNCTION("""COMPUTED_VALUE"""),43292.63611111111) -> 43292.636 | K27: =IFERROR(__xludf.DUMMYFUNCTION("""COMPUTED_VALUE"""),17.46) -> 17.46 | M27: =If((E27<$H$2),"CRASH","") | N27: =IF(I27>$O$3,"PREDICT CRASH","")
A28: =IFERROR(__xludf.DUMMYFUNCTION("""COMPUTED_VALUE"""),43293.66666666667) -> 43293.667 | B28: =IFERROR(__xludf.DUMMYFUNCTION("""COMPUTED_VALUE"""),2798.29) -> 2798.29 | C28: =IFERROR(__xludf.DUMMYFUNCTION("""COMPUTED_VALUE"""),43293.63611111111) -> 43293.636 | D28: =IFERROR(__xludf.DUMMYFUNCTION("""COMPUTED_VALUE"""),12.58) -> 12.58 | E28: =B28/B27-1 -> 0.0087490357 | F28: =IFERROR(__xludf.DUMMYFUNCTION("""COMPUTED_VALUE"""),43293.63611111111) -> 43293.636 | G28: =IFERROR(__xludf.DUMMYFUNCTION("""COMPUTED_VALUE"""),14.76) -> 14.76 | H28: =IFERROR(__xludf.DUMMYFUNCTION("""COMPUTED_VALUE"""),43293.63611111111) -> 43293.636 | I28: =IFERROR(__xludf.DUMMYFUNCTION("""COMPUTED_VALUE"""),16.1) -> 16.1 | J28: =IFERROR(__xludf.DUMMYFUNCTION("""COMPUTED_VALUE"""),43293.63611111111) -> 43293.636 | K28: =IFERROR(__xludf.DUMMYFUNCTION("""COMPUTED_VALUE"""),17.22) -> 17.22 | M28: =If((E28<$H$2),"CRASH","") | N28: =IF(I28>$O$3,"PREDICT CRASH","")
A29: =IFERROR(__xludf.DUMMYFUNCTION("""COMPUTED_VALUE"""),43294.66666666667) -> 43294.667 | B29: =IFERROR(__xludf.DUMMYFUNCTION("""COMPUTED_VALUE"""),2801.31) -> 2801.31 | C29: =IFERROR(__xludf.DUMMYFUNCTION("""COMPUTED_VALUE"""),43294.63611111111) -> 43294.636 | D29: =IFERROR(__xludf.DUMMYFUNCTION("""COMPUTED_VALUE"""),12.18) -> 12.18 | E29: =B29/B28-1 -> 0.0010792305 | F29: =IFERROR(__xludf.DUMMYFUNCTION("""COMPUTED_VALUE"""),43294.63611111111) -> 43294.636 | G29: =IFERROR(__xludf.DUMMYFUNCTION("""COMPUTED_VALUE"""),14.54) -> 14.54 | H29: =IFERROR(__xludf.DUMMYFUNCTION("""COMPUTED_VALUE"""),43294.63611111111) -> 43294.636 | I29: =IFERROR(__xludf.DUMMYFUNCTION("""COMPUTED_VALUE"""),15.9) -> 15.9 | J29: =IFERROR(__xludf.DUMMYFUNCTION("""COMPUTED_VALUE"""),43294.63611111111) -> 43294.636 | K29: =IFERROR(__xludf.DUMMYFUNCTION("""COMPUTED_VALUE"""),17.11) -> 17.11 | M29: =If((E29<$H$2),"CRASH","") | N29: =IF(I29>$O$3,"PREDICT CRASH","")
A30: =IFERROR(__xludf.DUMMYFUNCTION("""COMPUTED_VALUE"""),43297.66666666667) -> 43297.667 | B30: =IFERROR(__xludf.DUMMYFUNCTION("""COMPUTED_VALUE"""),2798.43) -> 2798.43 | C30: =IFERROR(__xludf.DUMMYFUNCTION("""COMPUTED_VALUE"""),43297.63611111111) -> 43297.636 | D30: =IFERROR(__xludf.DUMMYFUNCTION("""COMPUTED_VALUE"""),12.83) -> 12.83 | E30: =B30/B29-1 -> -0.0010280904 | F30: =IFERROR(__xludf.DUMMYFUNCTION("""COMPUTED_VALUE"""),43297.63611111111) -> 43297.636 | G30: =IFERROR(__xludf.DUMMYFUNCTION("""COMPUTED_VALUE"""),14.85) -> 14.85 | H30: =IFERROR(__xludf.DUMMYFUNCTION("""COMPUTED_VALUE"""),43297.63611111111) -> 43297.636 | I30: =IFERROR(__xludf.DUMMYFUNCTION("""COMPUTED_VALUE"""),16.1) -> 16.1 | J30: =IFERROR(__xludf.DUMMYFUNCTION("""COMPUTED_VALUE"""),43297.63611111111) -> 43297.636 | K30: =IFERROR(__xludf.DUMMYFUNCTION("""COMPUTED_VALUE"""),17.21) -> 17.21 | M30: =If((E30<$H$2),"CRASH","") | N30: =IF(I30>$O$3,"PREDICT CRASH","")
A31: =IFERROR(__xludf.DUMMYFUNCTION("""COMPUTED_VALUE"""),43298.66666666667) -> 43298.667 | B31: =IFERROR(__xludf.DUMMYFUNCTION("""COMPUTED_VALUE"""),2809.55) -> 2809.55 | C31: =IFERROR(__xludf.DUMMYFUNCTION("""COMPUTED_VALUE"""),43298.63611111111) -> 43298.636 | D31: =IFERROR(__xludf.DUMMYFUNCTION("""COMPUTED_VALUE"""),12.06) -> 12.06 | E31: =B31/B30-1 -> 0.0039736567 | F31: =IFERROR(__xludf.DUMMYFUNCTION("""COMPUTED_VALUE"""),43298.63611111111) -> 43298.636 | G31: =IFERROR(__xludf.DUMMYFUNCTION("""COMPUTED_VALUE"""),14.4) -> 14.4 | H31: =IFERROR(__xludf.DUMMYFUNCTION("""COMPUTED_VALUE"""),43298.63611111111) -> 43298.636 | I31: =IFERROR(__xludf.DUMMYFUNCTION("""COMPUTED_VALUE"""),15.83) -> 15.83 | J31: =IFERROR(__xludf.DUMMYFUNCTION("""COMPUTED_VALUE"""),43298.63611111111) -> 43298.636 | K31: =IFERROR(__xludf.DUMMYFUNCTION("""COMPUTED_VALUE"""),17.14) -> 17.14 | M31: =If((E31<$H$2),"CRASH","") | N31: =IF(I31>$O$3,"PREDICT CRASH","")
A32: =IFERROR(__xludf.DUMMYFUNCTION("""COMPUTED_VALUE"""),43299.66666666667) -> 43299.667 | B32: =IFERROR(__xludf.DUMMYFUNCTION("""COMPUTED_VALUE"""),2815.62) -> 2815.62 | C32: =IFERROR(__xludf.DUMMYFUNCTION("""COMPUTED_VALUE"""),43299.63611111111) -> 43299.636 | D32: =IFERROR(__xludf.DUMMYFUNCTION("""COMPUTED_VALUE"""),12.1) -> 12.1 | E32: =B32/B31-1 -> 0.0021604883 | F32: =IFERROR(__xludf.DUMMYFUNCTION("""COMPUTED_VALUE"""),43299.63611111111) -> 43299.636 | G32: =IFERROR(__xludf.DUMMYFUNCTION("""COMPUTED_VALUE"""),14.39) -> 14.39 | H32: =IFERROR(__xludf.DUMMYFUNCTION("""COMPUTED_VALUE"""),43299.63611111111) -> 43299.636 | I32: =IFERROR(__xludf.DUMMYFUNCTION("""COMPUTED_VALUE"""),15.88) -> 15.88 | J32: =IFERROR(__xludf.DUMMYFUNCTION("""COMPUTED_VALUE"""),43299.63611111111) -> 43299.636 | K32: =IFERROR(__xludf.DUMMYFUNCTION("""COMPUTED_VALUE"""),17.17) -> 17.17 | M32: =If((E32<$H$2),"CRASH","") | N32: =IF(I32>$O$3,"PREDICT CRASH","")
A33: =IFERROR(__xludf.DUMMYFUNCTION("""COMPUTED_VALUE"""),43300.66666666667) -> 43300.667 | B33: =IFERROR(__xludf.DUMMYFUNCTION("""COMPUTED_VALUE"""),2804.49) -> 2804.49 | C33: =IFERROR(__xludf.DUMMYFUNCTION("""COMPUTED_VALUE"""),43300.63611111111) -> 43300.636 | D33: =IFERROR(__xludf.DUMMYFUNCTION("""COMPUTED_VALUE"""),12.87) -> 12.87 | E33: =B33/B32-1 -> -0.0039529482 | F33: =IFERROR(__xludf.DUMMYFUNCTION("""COMPUTED_VALUE"""),43300.63611111111) -> 43300.636 | G33: =IFERROR(__xludf.DUMMYFUNCTION("""COMPUTED_VALUE"""),14.97) -> 14.97 | H33: =IFERROR(__xludf.DUMMYFUNCTION("""COMPUTED_VALUE"""),43300.63611111111) -> 43300.636 | I33: =IFERROR(__xludf.DUMMYFUNCTION("""COMPUTED_VALUE"""),16.22) -> 16.22 | J33: =IFERROR(__xludf.DUMMYFUNCTION("""COMPUTED_VALUE"""),43300.63611111111) -> 43300.636 | K33: =IFERROR(__xludf.DUMMYFUNCTION("""COMPUTED_VALUE"""),17.41) -> 17.41 | M33: =If((E33<$H$2),"CRASH","") | N33: =IF(I33>$O$3,"PREDICT CRASH","")
A34: =IFERROR(__xludf.DUMMYFUNCTION("""COMPUTED_VALUE"""),43301.66666666667) -> 43301.667 | B34: =IFERROR(__xludf.DUMMYFUNCTION("""COMPUTED_VALUE"""),2801.83) -> 2801.83 | C34: =IFERROR(__xludf.DUMMYFUNCTION("""COMPUTED_VALUE"""),43301.63611111111) -> 43301.636 | D34: =IFERROR(__xludf.DUMMYFUNCTION("""COMPUTED_VALUE"""),12.86) -> 12.86 | E34: =B34/B33-1 -> -0.00094847905 | F34: =IFERROR(__xludf.DUMMYFUNCTION("""COMPUTED_VALUE"""),43301.63611111111) -> 43301.636 | G34: =IFERROR(__xludf.DUMMYFUNCTION("""COMPUTED_VALUE"""),15.08) -> 15.08 | H34: =IFERROR(__xludf.DUMMYFUNCTION("""COMPUTED_VALUE"""),43301.63611111111) -> 43301.636 | I34: =IFERROR(__xludf.DUMMYFUNCTION("""COMPUTED_VALUE"""),16.41) -> 16.41 | J34: =IFERROR(__xludf.DUMMYFUNCTION("""COMPUTED_VALUE"""),43301.63611111111) -> 43301.636 | K34: =IFERROR(__xludf.DUMMYFUNCTION("""COMPUTED_VALUE"""),17.62) -> 17.62 | M34: =If((E34<$H$2),"CRASH","") | N34: =IF(I34>$O$3,"PREDICT CRASH","")
A35: =IFERROR(__xludf.DUMMYFUNCTION("""COMPUTED_VALUE"""),43304.66666666667) -> 43304.667 | B35: =IFERROR(__xludf.DUMMYFUNCTION("""COMPUTED_VALUE"""),2806.98) -> 2806.98 | C35: =IFERROR(__xludf.DUMMYFUNCTION("""COMPUTED_VALUE"""),43304.63611111111) -> 43304.636 | D35: =IFERROR(__xludf.DUMMYFUNCTION("""COMPUTED_VALUE"""),12.62) -> 12.62 | E35: =B35/B34-1 -> 0.0018380844 | F35: =IFERROR(__xludf.DUMMYFUNCTION("""COMPUTED_VALUE"""),43304.63611111111) -> 43304.636 | G35: =IFERROR(__xludf.DUMMYFUNCTION("""COMPUTED_VALUE"""),14.86) -> 14.86 | H35: =IFERROR(__xludf.DUMMYFUNCTION("""COMPUTED_VALUE"""),43304.63611111111) -> 43304.636 | I35: =IFERROR(__xludf.DUMMYFUNCTION("""COMPUTED_VALUE"""),16.24) -> 16.24 | J35: =IFERROR(__xludf.DUMMYFUNCTION("""COMPUTED_VALUE"""),43304.63611111111) -> 43304.636 | K35: =IFERROR(__xludf.DUMMYFUNCTION("""COMPUTED_VALUE"""),17.45) -> 17.45 | M35: =If((E35<$H$2),"CRASH","") | N35: =IF(I35>$O$3,"PREDICT CRASH","")
A36: =IFERROR(__xludf.DUMMYFUNCTION("""COMPUTED_VALUE"""),43305.66666666667) -> 43305.667 | B36: =IFERROR(__xludf.DUMMYFUNCTION("""COMPUTED_VALUE"""),2820.4) -> 2820.4 | C36: =IFERROR(__xludf.DUMMYFUNCTION("""COMPUTED_VALUE"""),43305.63611111111) -> 43305.636 | D36: =IFERROR(__xludf.DUMMYFUNCTION("""COMPUTED_VALUE"""),12.41) -> 12.41 | E36: =B36/B35-1 -> 0.0047809389 | F36: =IFERROR(__xludf.DUMMYFUNCTION("""COMPUTED_VALUE"""),43305.63611111111) -> 43305.636 | G36: =IFERROR(__xludf.DUMMYFUNCTION("""COMPUTED_VALUE"""),14.7) -> 14.7 | H36: =IFERROR(__xludf.DUMMYFUNCTION("""COMPUTED_VALUE"""),43305.63611111111) -> 43305.636 | I36: =IFERROR(__xludf.DUMMYFUNCTION("""COMPUTED_VALUE"""),16.09) -> 16.09 | J36: =IFERROR(__xludf.DUMMYFUNCTION("""COMPUTED_VALUE"""),43305.63611111111) -> 43305.636 | K36: =IFERROR(__xludf.DUMMYFUNCTION("""COMPUTED_VALUE"""),17.33) -> 17.33 | M36: =If((E36<$H$2),"CRASH","") | N36: =IF(I36>$O$3,"PREDICT CRASH","")
A37: =IFERROR(__xludf.DUMMYFUNCTION("""COMPUTED_VALUE"""),43306.66666666667) -> 43306.667 | B37: =IFERROR(__xludf.DUMMYFUNCTION("""COMPUTED_VALUE"""),2846.07) -> 2846.07 | C37: =IFERROR(__xludf.DUMMYFUNCTION("""COMPUTED_VALUE"""),43306.63611111111) -> 43306.636 | D37: =IFERROR(__xludf.DUMMYFUNCTION("""COMPUTED_VALUE"""),12.29) -> 12.29 | E37: =B37/B36-1 -> 0.0091015459 | F37: =IFERROR(__xludf.DUMMYFUNCTION("""COMPUTED_VALUE"""),43306.63611111111) -> 43306.636 | G37: =IFERROR(__xludf.DUMMYFUNCTION("""COMPUTED_VALUE"""),14.55) -> 14.55 | H37: =IFERROR(__xludf.DUMMYFUNCTION("""COMPUTED_VALUE"""),43306.63611111111) -> 43306.636 | I37: =IFERROR(__xludf.DUMMYFUNCTION("""COMPUTED_VALUE"""),15.89) -> 15.89 | J37: =IFERROR(__xludf.DUMMYFUNCTION("""COMPUTED_VALUE"""),43306.63611111111) -> 43306.636 | K37: =IFERROR(__xludf.DUMMYFUNCTION("""COMPUTED_VALUE"""),17.14) -> 17.14 | M37: =If((E37<$H$2),"CRASH","") | N37: =IF(I37>$O$3,"PREDICT CRASH","")
A38: =IFERROR(__xludf.DUMMYFUNCTION("""COMPUTED_VALUE"""),43307.66666666667) -> 43307.667 | B38: =IFERROR(__xludf.DUMMYFUNCTION("""COMPUTED_VALUE"""),2837.44) -> 2837.44 | C38: =IFERROR(__xludf.DUMMYFUNCTION("""COMPUTED_VALUE"""),43307.63611111111) -> 43307.636 | D38: =IFERROR(__xludf.DUMMYFUNCTION("""COMPUTED_VALUE"""),12.14) -> 12.14 | E38: =B38/B37-1 -> -0.0030322515 | F38: =IFERROR(__xludf.DUMMYFUNCTION("""COMPUTED_VALUE"""),43307.63611111111) -> 43307.636 | G38: =IFERROR(__xludf.DUMMYFUNCTION("""COMPUTED_VALUE"""),14.4) -> 14.4 | H38: =IFERROR(__xludf.DUMMYFUNCTION("""COMPUTED_VALUE"""),43307.63611111111) -> 43307.636 | I38: =IFERROR(__xludf.DUMMYFUNCTION("""COMPUTED_VALUE"""),15.87) -> 15.87 | J38: =IFERROR(__xludf.DUMMYFUNCTION("""COMPUTED_VALUE"""),43307.63611111111) -> 43307.636 | K38: =IFERROR(__xludf.DUMMYFUNCTION("""COMPUTED_VALUE"""),17.18) -> 17.18 | M38: =If((E38<$H$2),"CRASH","") | N38: =IF(I38>$O$3,"PREDICT CRASH","")
A39: =IFERROR(__xludf.DUMMYFUNCTION("""COMPUTED_VALUE"""),43308.66666666667) -> 43308.667 | B39: =IFERROR(__xludf.DUMMYFUNCTION("""COMPUTED_VALUE"""),2818.82) -> 2818.82 | C39: =IFERROR(__xludf.DUMMYFUNCTION("""COMPUTED_VALUE"""),43308.63611111111) -> 43308.636 | D39: =IFERROR(__xludf.DUMMYFUNCTION("""COMPUTED_VALUE"""),13.03) -> 13.03 | E39: =B39/B38-1 -> -0.0065622533 | F39: =IFERROR(__xludf.DUMMYFUNCTION("""COMPUTED_VALUE"""),43308.63611111111) -> 43308.636 | G39: =IFERROR(__xludf.DUMMYFUNCTION("""COMPUTED_VALUE"""),15.0) -> 15 | H39: =IFERROR(__xludf.DUMMYFUNCTION("""COMPUTED_VALUE"""),43308.63611111111) -> 43308.636 | I39: =IFERROR(__xludf.DUMMYFUNCTION("""COMPUTED_VALUE"""),16.22) -> 16.22 | J39: =IFERROR(__xludf.DUMMYFUNCTION("""COMPUTED_VALUE"""),43308.63611111111) -> 43308.636 | K39: =IFERROR(__xludf.DUMMYFUNCTION("""COMPUTED_VALUE"""),17.33) -> 17.33 | M39: =If((E39<$H$2),"CRASH","") | N39: =IF(I39>$O$3,"PREDICT CRASH","")
A40: =IFERROR(__xludf.DUMMYFUNCTION("""COMPUTED_VALUE"""),43311.66666666667) -> 43311.667 | B40: =IFERROR(__xludf.DUMMYFUNCTION("""COMPUTED_VALUE"""),2802.6) -> 2802.6 | C40: =IFERROR(__xludf.DUMMYFUNCTION("""COMPUTED_VALUE"""),43311.63611111111) -> 43311.636 | D40: =IFERROR(__xludf.DUMMYFUNCTION("""COMPUTED_VALUE"""),14.26) -> 14.26 | E40: =B40/B39-1 -> -0.0057541808 | F40: =IFERROR(__xludf.DUMMYFUNCTION("""COMPUTED_VALUE"""),43311.63611111111) -> 43311.636 | G40: =IFERROR(__xludf.DUMMYFUNCTION("""COMPUTED_VALUE"""),15.66) -> 15.66 | H40: =IFERROR(__xludf.DUMMYFUNCTION("""COMPUTED_VALUE"""),43311.63611111111) -> 43311.636 | I40: =IFERROR(__xludf.DUMMYFUNCTION("""COMPUTED_VALUE"""),16.68) -> 16.68 | J40: =IFERROR(__xludf.DUMMYFUNCTION("""COMPUTED_VALUE"""),43311.63611111111) -> 43311.636 | K40: =IFERROR(__xludf.DUMMYFUNCTION("""COMPUTED_VALUE"""),17.66) -> 17.66 | M40: =If((E40<$H$2),"CRASH","") | N40: =IF(I40>$O$3,"PREDICT CRASH","")
...

Sheet VIXHISTORIQUEMODEL
A1: Date | B1: SPX | C1: VIX | D1: VIX3M | E1: VIX6M | F1: VIX1Y
A2: ='VIX HISTORIQUE'!A5 -> 43259.667 | B2: ='VIX HISTORIQUE'!B5 -> 2779.03 | C2: ='VIX HISTORIQUE'!D5 -> 12.18 | D2: ='VIX HISTORIQUE'!G5 -> 14.6 | E2: ='VIX HISTORIQUE'!I5 -> 16.13 | F2: ='VIX HISTORIQUE'!K5 -> 17.23
A3: ='VIX HISTORIQUE'!A6 -> 43262.667 | B3: ='VIX HISTORIQUE'!B6 -> 2782 | C3: ='VIX HISTORIQUE'!D6 -> 12.35 | D3: ='VIX HISTORIQUE'!G6 -> 14.55 | E3: ='VIX HISTORIQUE'!I6 -> 16.12 | F3: ='VIX HISTORIQUE'!K6 -> 17.17
A4: ='VIX HISTORIQUE'!A7 -> 43263.667 | B4: ='VIX HISTORIQUE'!B7 -> 2786.85 | C4: ='VIX HISTORIQUE'!D7 -> 12.34 | D4: ='VIX HISTORIQUE'!G7 -> 14.59 | E4: ='VIX HISTORIQUE'!I7 -> 16.17 | F4: ='VIX HISTORIQUE'!K7 -> 17.23
A5: ='VIX HISTORIQUE'!A8 -> 43264.667 | B5: ='VIX HISTORIQUE'!B8 -> 2775.63 | C5: ='VIX HISTORIQUE'!D8 -> 12.94 | D5: ='VIX HISTORIQUE'!G8 -> 14.92 | E5: ='VIX HISTORIQUE'!I8 -> 16.43 | F5: ='VIX HISTORIQUE'!K8 -> 17.44
A6: ='VIX HISTORIQUE'!A9 -> 43265.667 | B6: ='VIX HISTORIQUE'!B9 -> 2782.49 | C6: ='VIX HISTORIQUE'!D9 -> 12.12 | D6: ='VIX HISTORIQUE'!G9 -> 14.4 | E6: ='VIX HISTORIQUE'!I9 -> 16.09 | F6: ='VIX HISTORIQUE'!K9 -> 17.31
A7: ='VIX HISTORIQUE'!A10 -> 43266.667 | B7: ='VIX HISTORIQUE'!B10 -> 2779.66 | C7: ='VIX HISTORIQUE'!D10 -> 11.98 | D7: ='VIX HISTORIQUE'!G10 -> 14.42 | E7: ='VIX HISTORIQUE'!I10 -> 16.32 | F7: ='VIX HISTORIQUE'!K10 -> 17.54
A8: ='VIX HISTORIQUE'!A11 -> 43269.667 | B8: ='VIX HISTORIQUE'!B11 -> 2773.75 | C8: ='VIX HISTORIQUE'!D11 -> 12.31 | D8: ='VIX HISTORIQUE'!G11 -> 14.48 | E8: ='VIX HISTORIQUE'!I11 -> 16.35 | F8: ='VIX HISTORIQUE'!K11 -> 17.61
A9: ='VIX HISTORIQUE'!A12 -> 43270.667 | B9: ='VIX HISTORIQUE'!B12 -> 2762.59 | C9: ='VIX HISTORIQUE'!D12 -> 13.35 | D9: ='VIX HISTORIQUE'!G12 -> 15.17 | E9: ='VIX HISTORIQUE'!I12 -> 16.89 | F9: ='VIX HISTORIQUE'!K12 -> 18.09
A10: ='VIX HISTORIQUE'!A13 -> 43271.667 | B10: ='VIX HISTORIQUE'!B13 -> 2767.32 | C10: ='VIX HISTORIQUE'!D13 -> 12.79 | D10: ='VIX HISTORIQUE'!G13 -> 14.79 | E10: ='VIX HISTORIQUE'!I13 -> 16.52 | F10: ='VIX HISTORIQUE'!K13 -> 17.77
A11: ='VIX HISTORIQUE'!A14 -> 43272.667 | B11: ='VIX HISTORIQUE'!B14 -> 2749.76 | C11: ='VIX HISTORIQUE'!D14 -> 14.64 | D11: ='VIX HISTORIQUE'!G14 -> 15.87 | E11: ='VIX HISTORIQUE'!I14 -> 17.2 | F11: ='VIX HISTORIQUE'!K14 -> 18.18
A12: ='VIX HISTORIQUE'!A15 -> 43273.667 | B12: ='VIX HISTORIQUE'!B15 -> 2754.88 | C12: ='VIX HISTORIQUE'!D15 -> 13.77 | D12: ='VIX HISTORIQUE'!G15 -> 15.5 | E12: ='VIX HISTORIQUE'!I15 -> 16.92 | F12: ='VIX HISTORIQUE'!K15 -> 18.12
A13: ='VIX HISTORIQUE'!A16 -> 43276.667 | B13: ='VIX HISTORIQUE'!B16 -> 2717.07 | C13: ='VIX HISTORIQUE'!D16 -> 17.33 | D13: ='VIX HISTORIQUE'!G16 -> 17.52 | E13: ='VIX HISTORIQUE'!I16 -> 18.27 | F13: ='VIX HISTORIQUE'!K16 -> 18.87
... A1340: ='VIX HISTORIQUE'!A1343 -> 45210.667 | B1340: ='VIX HISTORIQUE'!B1343 -> 4376.95 | C1340: ='VIX HISTORIQUE'!D1343 -> 16.09 | D1340: ='VIX HISTORIQUE'!G1343 -> 17.63 | E1340: ='VIX HISTORIQUE'!I1343 -> 19.63 | F1340: ='VIX HISTORIQUE'!K1343 -> 21.86
A1349: ='VIX HISTORIQUE'!A1344 -> 45211.667 | B1349: ='VIX HISTORIQUE'!B1344 -> 4349.61 | C1349: ='VIX HISTORIQUE'!D1344 -> 16.69 | D1349: ='VIX HISTORIQUE'!G1344 -> 18.09 | E1349: ='VIX HISTORIQUE'!I1344 -> 19.98 | F1349: ='VIX HISTORIQUE'!K1344 -> 22.08
A1350: ='VIX HISTORIQUE'!A1345 -> 45212.667 | B1350: ='VIX HISTORIQUE'!B1345 -> 4327.78 | C1350: ='VIX HISTORIQUE'!D1345 -> 19.32 | D1350: ='VIX HISTORIQUE'!G1345 -> 20.57 | E1350: ='VIX HISTORIQUE'!I1345 -> 21.81 | F1350: ='VIX HISTORIQUE'!K1345 -> 23.25
A1351: ='VIX HISTORIQUE'!A1346 -> 45215.667 | B1351: ='VIX HISTORIQUE'!B1346 -> 4373.63 | C1351: ='VIX HISTORIQUE'!D1346 -> 17.21 | D1351: ='VIX HISTORIQUE'!G1346 -> 18.79 | E1351: ='VIX HISTORIQUE'!I1346 -> 20.64 | F1351: ='VIX HISTORIQUE'!K1346 -> 22.62
A1352: ='VIX HISTORIQUE'!A1347 -> 45216.667 | B1352: ='VIX HISTORIQUE'!B1347 -> 4373.2 | C1352: ='VIX HISTORIQUE'!D1347 -> 17.88 | D1352: ='VIX HISTORIQUE'!G1347 -> 19.26 | E1352: ='VIX HISTORIQUE'!I1347 -> 21.06 | F1352: ='VIX HISTORIQUE'!K1347 -> 22.93
A1353: ='VIX HISTORIQUE'!A1348 -> 45217.667 | B1353: ='VIX HISTORIQUE'!B1348 -> 4314.6 | C1353: ='VIX HISTORIQUE'!D1348 -> 19.22 | D1353: ='VIX HISTORIQUE'!G1348 -> 20.47 | E1353: ='VIX HISTORIQUE'!I1348 -> 21.96 | F1353: ='VIX HISTORIQUE'!K1348 -> 23.55
A1354: ='VIX HISTORIQUE'!A1349 -> 45218.667 | B1354: ='VIX HISTORIQUE'!B1349 -> 4278 | C1354: ='VIX HISTORIQUE'!D1349 -> 21.4 | D1354: ='VIX HISTORIQUE'!G1349 -> 22.19 | E1354: ='VIX HISTORIQUE'!I1349 -> 23.21 | F1354: ='VIX HISTORIQUE'!K1349 -> 24.39
A1355: ='VIX HISTORIQUE'!A1350 -> 45219.667 | B1355: ='VIX HISTORIQUE'!B1350 -> 4224.16 | C1355: ='VIX HISTORIQUE'!D1350 -> 21.71 | D1355: ='VIX HISTORIQUE'!G1350 -> 22.44 | E1355: ='VIX HISTORIQUE'!I1350 -> 23.6 | F1355: ='VIX HISTORIQUE'!K1350 -> 24.61
A1356: ='VIX HISTORIQUE'!A1351 -> 45222.667 | B1356: ='VIX HISTORIQUE'!B1351 -> 4217.04 | C1356: ='VIX HISTORIQUE'!D1351 -> 20.37 | D1356: ='VIX HISTORIQUE'!G1351 -> 21.33 | E1356: ='VIX HISTORIQUE'!I1351 -> 22.67 | F1356: ='VIX HISTORIQUE'!K1351 -> 24.03
A1357: ='VIX HISTORIQUE'!A1352 -> 45223.667 | B1357: ='VIX HISTORIQUE'!B1352 -> 4247.68 | C1357: ='VIX HISTORIQUE'!D1352 -> 18.97 | D1357: ='VIX HISTORIQUE'!G1352 -> 20.21 | E1357: ='VIX HISTORIQUE'!I1352 -> 21.85 | F1357: ='VIX HISTORIQUE'!K1352 -> 23.47
A1358: ='VIX HISTORIQUE'!A1353 -> 45224.667 | B1358: ='VIX HISTORIQUE'!B1353 -> 4186.77 | C1358: ='VIX HISTORIQUE'!D1353 -> 20.19 | D1358: ='VIX HISTORIQUE'!G1353 -> 21.33 | E1358: ='VIX HISTORIQUE'!I1353 -> 22.69 | F1358: ='VIX HISTORIQUE'!K1353 -> 24.04
A1359: ='VIX HISTORIQUE'!A1354 -> 45225.667 | B1359: ='VIX HISTORIQUE'!B1354 -> 4137.23 | C1359: ='VIX HISTORIQUE'!D1354 -> 20.68 | D1359: ='VIX HISTORIQUE'!G1354 -> 21.57 | E1359: ='VIX HISTORIQUE'!I1354 -> 23.02 | F1359: ='VIX HISTORIQUE'!K1354 -> 24.31
A1360: ='VIX HISTORIQUE'!A1355 -> 45226.667 | B1360: ='VIX HISTORIQUE'!B1355 -> 4117.37 | C1360: ='VIX HISTORIQUE'!D1355 -> 21.27 | D1360: ='VIX HISTORIQUE'!G1355 -> 22.27 | E1360: ='VIX HISTORIQUE'!I1355 -> 23.65 | F1360: ='VIX HISTORIQUE'!K1355 -> 24.48
... A1602: ='VIX HISTORIQUE'!A1597 -> 45580.667 | B1602: ='VIX HISTORIQUE'!B1597 -> 5815.26 | C1602: ='VIX HISTORIQUE'!D1597 -> 20.64 | D1602: ='VIX HISTORIQUE'!G1597 -> 20.8 | E1602: ='VIX HISTORIQUE'!I1597 -> 21.14 | F1602: ='VIX HISTORIQUE'!K1597 -> 22.14
A1603: ='VIX HISTORIQUE'!A2119 | B1603: ='VIX HISTORIQUE'!B2119 | C1603: ='VIX HISTORIQUE'!D2119 | D1603: ='VIX HISTORIQUE'!G2119 | E1603: ='VIX HISTORIQUE'!I2119 | F1603: ='VIX HISTORIQUE'!K2119
A1604: ='VIX HISTORIQUE'!A2120 | B1604: ='VIX HISTORIQUE'!B2120 | C1604: ='VIX HISTORIQUE'!D2120 | D1604: ='VIX HISTORIQUE'!G2120 | E1604: ='VIX HISTORIQUE'!I2120 | F1604: ='VIX HISTORIQUE'!K2120
A1605: ='VIX HISTORIQUE'!A2121 | B1605: ='VIX HISTORIQUE'!B2121 | C1605: ='VIX HISTORIQUE'!D2121 | D1605: ='VIX HISTORIQUE'!G2121 | E1605: ='VIX HISTORIQUE'!I2121 | F1605: ='VIX HISTORIQUE'!K2121
A1606: ='VIX HISTORIQUE'!A2122 | B1606: ='VIX HISTORIQUE'!B2122 | C1606: ='VIX HISTORIQUE'!D2122 | D1606: ='VIX HISTORIQUE'!G2122 | E1606: ='VIX HISTORIQUE'!I2122 | F1606: ='VIX HISTORIQUE'!K2122
A1607: ='VIX HISTORIQUE'!A2123 | B1607: ='VIX HISTORIQUE'!B2123 | C1607: ='VIX HISTORIQUE'!D2123 | D1607: ='VIX HISTORIQUE'!G2123 | E1607: ='VIX HISTORIQUE'!I2123 | F1607: ='VIX HISTORIQUE'!K2123
A1608: ='VIX HISTORIQUE'!A2124 | B1608: ='VIX HISTORIQUE'!B2124 | C1608: ='VIX HISTORIQUE'!D2124 | D1608: ='VIX HISTORIQUE'!G2124 | E1608: ='VIX HISTORIQUE'!I2124 | F1608: ='VIX HISTORIQUE'!K2124
A1609: ='VIX HISTORIQUE'!A2125 | B1609: ='VIX HISTORIQUE'!B2125 | C1609: ='VIX HISTORIQUE'!D2125 | D1609: ='VIX HISTORIQUE'!G2125 | E1609: ='VIX HISTORIQUE'!I2125 | F1609: ='VIX HISTORIQUE'!K2125
A1610: ='VIX HISTORIQUE'!A2126 | B1610: ='VIX HISTORIQUE'!B2126 | C1610: ='VIX HISTORIQUE'!D2126 | D1610: ='VIX HISTORIQUE'!G2126 | E1610: ='VIX HISTORIQUE'!I2126 | F1610: ='VIX HISTORIQUE'!K2126
A1611: ='VIX HISTORIQUE'!A2127 | B1611: ='VIX HISTORIQUE'!B2127 | C1611: ='VIX HISTORIQUE'!D2127 | D1611: ='VIX HISTORIQUE'!G2127 | E1611: ='VIX HISTORIQUE'!I2127 | F1611: ='VIX HISTORIQUE'!K2127
A1612: ='VIX HISTORIQUE'!A2128 | B1612: ='VIX HISTORIQUE'!B2128 | C1612: ='VIX HISTORIQUE'!D2128 | D1612: ='VIX HISTORIQUE'!G2128 | E1612: ='VIX HISTORIQUE'!I2128 | F1612: ='VIX HISTORIQUE'!K2128
A1613: ='VIX HISTORIQUE'!A2129 | B1613: ='VIX HISTORIQUE'!B2129 | C1613: ='VIX HISTORIQUE'!D2129 | D1613: ='VIX HISTORIQUE'!G2129 | E1613: ='VIX HISTORIQUE'!I2129 | F1613: ='VIX HISTORIQUE'!K2129
A1614: ='VIX HISTORIQUE'!A2130 | B1614: ='VIX HISTORIQUE'!B2130 | C1614: ='VIX HISTORIQUE'!D2130 | D1614: ='VIX HISTORIQUE'!G2130 | E1614: ='VIX HISTORIQUE'!I2130 | F1614: ='VIX HISTORIQUE'!K2130
... A1624: ='VIX HISTORIQUE'!A2140 | B1624: ='VIX HISTORIQUE'!B2140 | C1624: ='VIX HISTORIQUE'!D2140 | D1624: ='VIX HISTORIQUE'!G2140 | E1624: ='VIX HISTORIQUE'!I2140 | F1624: ='VIX HISTORIQUE'!K2140

Sheet Portfolio
A1: ASSET | B1: CURRENCY | C1: GCODE | D1: ISIN | E1: DESCR | F1: MAT | G1: YTM | H1: LibelléISIN | I1: Quantité | J1: Prix de revient | K1: Place de Cotation | L1: Cours en devise | M1: Cours/VL | N1: Date du cours / VL | O1: Valorisation * | P1: "+/- Values latentes" | Q1: Performance** | R1: Poids %
A2: OBLIGATION | B2: EUR | C2: 28ID | D2: IE0000UJ3480 | E2: US CORPORATE, US A 45%, BBB 55% | F2: 45654 | G2: 4.5 | H2: IS.IBD.DEC.28 T.USD UC.ETF USD IE0000UJ3480 | I2: 1 015 | J2: 98,55 € | K2: Paris | L2: 99,3746 EUR | M2: 993746 | N2: 45361 | O2: 100 865,22 € | P2: 836,97 € | Q2: 0,84 % | R2: 9.4964161
A3: OBLIGATION | B3: EUR | C3: IB27 | D3: IE000ZOI8OK5 | E3: EURO CORPORATE , A Or AA 50%, BBB 50% | F3: 45653 | G3: 3.1 | H3: ISHARES IBONDS DEC 2027 ¤ CORP IE000ZOI8OK5 | I3: 9 435 | J3: 5,30 € | K3: Frankfurt_ETF_ETP | L3: 5,3822 EUR | M3: 53822 | N3: 45361 | O3: 50 781,06 € | P3: 775,56 € | Q3: 1,55 % | R3: 4.7838018
A4: OBLIGATION | B4: EUR | C4: 26ID | D4: IE000BWITBP9 | E4: US CORPORATE, A or AA 60%, BBB 40% | F4: 45652 | G4: 4.5 | H4: ISHRS IBD DEC 26 USD -ACC IE000BWITBP9 | I4: 2 040 | J4: 9794870 | K4: London | L4: 108,07 USD | M4: 9789836 | N4: 45361 | O4: 199 712,66 € | P4: -102,69 € | Q4: -0,05 % | R4: 18.807745
A5: OBLIGATION | B5: EUR | C5: IB25 | D5: IE000GUOATN7 | E5: EURO CORPORATE , A Or AA 50%, BBB 50% | F5: 45651 | G5: 3.5 | H5: ISHS IBONDS DEC25 UC.ETF C EUR IE000GUOATN7 | I5: 19 212 | J5: 5205 | K5: Frankfurt_ETF_ETP | L5: 5,2234 EUR | M5: 52234 | N5: 45361 | O5: 100 351,96 € | P5: 353,50 € | Q5: 0,35 % | R5: 9.4537035
A6: OBLIGATION | B6: EUR | C6: CEBE | D6: IE000WA6L436 | E6: EURO CORPORATE , A Or AA 55%, BBB 45% | F6: 45652 | G6: 3.2 | H6: ISHS IBONDS DEC26 UC.ETF C EUR IE000WA6L436 | I6: 19 665 | J6: 52508 | K6: Paris | L6: 5,313 EUR | M6: 5313 | N6: 45361 | O6: 104 480,15 € | P6: 1 223,17 € | Q6: 1,18 % | R6: 9.8381162
A7: OBLIGATION | B7: USD | C7: DI27 | D7: IE000I1D7D10 | E7: US CORPORATE, A Or AA 50%, BBB 50% | F7: 45653 | G7: 4.5 | H7: ISHS IBONDS DEC27 UC.ETF C USD IE000I1D7D10 | I7: 1 015 | J7: 98,70 € | K7: Paris | L7: 99,1209 EUR | M7: 991209 | N7: 45361 | O7: 100 607,71 € | P7: 427,21 € | Q7: 0,43 % | R7: 9.4821786
A8: OBLIGATION | B8: USD | C8: IVOA | D8: IE0008UEVOE0 | E8: EURO CORPORATE , A Or AA 50%, BBB 50% | F8: 45654 | G8: 3.2 | H8: ISHS IBONDS DEC28 UC.ETF C EUR IE0008UEVOE0 | I8: 9 375 | J8: 53343 | K8: Paris | L8: 5,432 EUR | M8: 5432 | N8: 45361 | O8: 50 925,00 € | P8: 915,94 € | Q8: 1,83 % | R8: 4.7980393
A9: EQUITY | B9: USD | C9: CSPX | D9: IE00B5BMR087 | E9: S&P ETF | H9: ISHARES CORE S&P 500 UCITS ETF IE00B5BMR087 | I9: 1400 | J9: 53444571 | K9: Frankfurt_ETF_ETP | L9: 545,48 EUR | M9: 545,48 € | N9: 45361 | O9: 763 672,00 € | P9: 15448,00 € | Q9: 2,06 % | R9: 33.333333
A10: OBLIGATION | B10: USD | C10: IHYA | D10: IE00BYXYYL56 | E10: BB 45, B 38, CCC and below 17 | F10: 3.6 YEAR | G10: 6.85
A11: OBLIGATION | B11: USD | C11: ID30 | D11: IE0008TDJ461 | E11: US CORPORATE, A or AA 42 BBB 48 | F11: 45656 | G11: 4.6
L15: 1

Sheet Historique
B1: PRODUCT | D1: DATE | E1: 2023 | F1: 9 | G1: 15 | I1: TYPE | J1: DAILY
B2: IE0000UJ3480 | D2: IE000ZOI8OK5 | F2: IE000BWITBP9 | H2: IE000GUOATN7 | J2: IE000WA6L436 | L2: IE000I1D7D10 | N2: IE0008UEVOE0 | P2: IE00B5BMR087 | T2: US46436E3797
B3: 28ID | D3: IB27 | F3: 26ID | H3: IB25 | J3: CEBE | L3: DI27 | N3: IVOA | P3: CSPX | R3: IBHI | T3: IHYA | V3: EURUSD
A4: =IFERROR(__xludf.DUMMYFUNCTION("GOOGLEFINANCE(B$3, ""price"", DATE($E$1, $F$1, $G$1), TODAY(), $J$1)"),"Date") -> Date | B4: =IFERROR(__xludf.DUMMYFUNCTION("""COMPUTED_VALUE"""),"Close") -> Close | C4: =IFERROR(__xludf.DUMMYFUNCTION("GOOGLEFINANCE(D$3, ""price"", DATE($E$1, $F$1, $G$1), TODAY(), $J$1)"),"Date") -> Date | D4: =IFERROR(__xludf.DUMMYFUNCTION("""COMPUTED_VALUE"""),"Close") -> Close | E4: =IFERROR(__xludf.DUMMYFUNCTION("GOOGLEFINANCE(F$3, ""price"", DATE($E$1, $F$1, $G$1), TODAY(), $J$1)"),"Date") -> Date | F4: =IFERROR(__xludf.DUMMYFUNCTION("""COMPUTED_VALUE"""),"Close") -> Close | G4: =IFERROR(__xludf.DUMMYFUNCTION("GOOGLEFINANCE(H$3, ""price"", DATE($E$1, $F$1, $G$1), TODAY(), $J$1)"),"Date") -> Date | H4: =IFERROR(__xludf.DUMMYFUNCTION("""COMPUTED_VALUE"""),"Close") -> Close | I4: =IFERROR(__xludf.DUMMYFUNCTION("GOOGLEFINANCE(J$3, ""price"", DATE($E$1, $F$1, $G$1), TODAY(), $J$1)"),"Date") -> Date | J4: =IFERROR(__xludf.DUMMYFUNCTION("""COMPUTED_VALUE"""),"Close") -> Close | K4: =IFERROR(__xludf.DUMMYFUNCTION("GOOGLEFINANCE(L$3, ""price"", DATE($E$1, $F$1, $G$1), TODAY(), $J$1)"),"Date") -> Date | L4: =IFERROR(__xludf.DUMMYFUNCTION("""COMPUTED_VALUE"""),"Close") -> Close | M4: =IFERROR(__xludf.DUMMYFUNCTION("GOOGLEFINANCE(N$3, ""price"", DATE($E$1, $F$1, $G$1), TODAY(), $J$1)"),"Date") -> Date | N4: =IFERROR(__xludf.DUMMYFUNCTION("""COMPUTED_VALUE"""),"Close") -> Close | O4: =IFERROR(__xludf.DUMMYFUNCTION("GOOGLEFINANCE(P$3, ""price"", DATE($E$1, $F$1, $G$1), TODAY(), $J$1)"),"Date") -> Date | P4: =IFERROR(__xludf.DUMMYFUNCTION("""COMPUTED_VALUE"""),"Close") -> Close | Q4: =IFERROR(__xludf.DUMMYFUNCTION("GOOGLEFINANCE(R$3, ""price"", DATE($E$1, $F$1, $G$1), TODAY(), $J$1)"),"Date") -> Date | R4: =IFERROR(__xludf.DUMMYFUNCTION("""COMPUTED_VALUE"""),"Close") -> Close | S4: =IFERROR(__xludf.DUMMYFUNCTION("GOOGLEFINANCE(T$3, ""price"", DATE($E$1, $F$1, $G$1), TODAY(), $J$1)"),"Date") -> Date | T4: =IFERROR(__xludf.DUMMYFUNCTION("""COMPUTED_VALUE"""),"Close") -> Close | U4: =IFERROR(__xludf.DUMMYFUNCTION("GOOGLEFINANCE(V$3, ""price"", DATE($E$1, $F$1, $G$1), TODAY(), $J$1)"),"Date") -> Date | V4: =IFERROR(__xludf.DUMMYFUNCTION("""COMPUTED_VALUE"""),"Close") -> Close
A5: =IFERROR(__xludf.DUMMYFUNCTION("""COMPUTED_VALUE"""),45184.73611111111) -> 45184.736 | B5: =IFERROR(__xludf.DUMMYFUNCTION("""COMPUTED_VALUE"""),93.05) -> 93.05 | C5: =IFERROR(__xludf.DUMMYFUNCTION("""COMPUTED_VALUE"""),45184.726388888885) -> 45184.726 | D5: =IFERROR(__xludf.DUMMYFUNCTION("""COMPUTED_VALUE"""),5.02) -> 5.02 | E5: =IFERROR(__xludf.DUMMYFUNCTION("""COMPUTED_VALUE"""),45184.73611111111) -> 45184.736 | F5: =IFERROR(__xludf.DUMMYFUNCTION("""COMPUTED_VALUE"""),93.43) -> 93.43 | G5: =IFERROR(__xludf.DUMMYFUNCTION("""COMPUTED_VALUE"""),45184.726388888885) -> 45184.726 | H5: =IFERROR(__xludf.DUMMYFUNCTION("""COMPUTED_VALUE"""),5.02) -> 5.02 | I5: =IFERROR(__xludf.DUMMYFUNCTION("""COMPUTED_VALUE"""),45184.726388888885) -> 45184.726 | J5: =IFERROR(__xludf.DUMMYFUNCTION("""COMPUTED_VALUE"""),5.02) -> 5.02 | K5: =IFERROR(__xludf.DUMMYFUNCTION("""COMPUTED_VALUE"""),45184.73611111111) -> 45184.736 | L5: =IFERROR(__xludf.DUMMYFUNCTION("""COMPUTED_VALUE"""),93.7) -> 93.7 | M5: =IFERROR(__xludf.DUMMYFUNCTION("""COMPUTED_VALUE"""),45184.726388888885) -> 45184.726 | N5: =IFERROR(__xludf.DUMMYFUNCTION("""COMPUTED_VALUE"""),5.02) -> 5.02 | O5: =IFERROR(__xludf.DUMMYFUNCTION("""COMPUTED_VALUE"""),45184.6875) -> 45184.688 | P5: =IFERROR(__xludf.DUMMYFUNCTION("""COMPUTED_VALUE"""),466.41) -> 466.41 | Q5: =IFERROR(__xludf.DUMMYFUNCTION("""COMPUTED_VALUE"""),45184.66666666667) -> 45184.667 | R5: =IFERROR(__xludf.DUMMYFUNCTION("""COMPUTED_VALUE"""),22.1) -> 22.1 | S5: =IFERROR(__xludf.DUMMYFUNCTION("""COMPUTED_VALUE"""),45184.6875) -> 45184.688 | T5: =IFERROR(__xludf.DUMMYFUNCTION("""COMPUTED_VALUE"""),5.96) -> 5.96 | U5: =IFERROR(__xludf.DUMMYFUNCTION("""COMPUTED_VALUE"""),45184.99861111111) -> 45184.999 | V5: =IFERROR(__xludf.DUMMYFUNCTION("""COMPUTED_VALUE"""),1.0672) -> 1.0672
A6: =IFERROR(__xludf.DUMMYFUNCTION("""COMPUTED_VALUE"""),45187.73611111111) -> 45187.736 | B6: =IFERROR(__xludf.DUMMYFUNCTION("""COMPUTED_VALUE"""),93.04) -> 93.04 | C6: =IFERROR(__xludf.DUMMYFUNCTION("""COMPUTED_VALUE"""),45187.726388888885) -> 45187.726 | D6: =IFERROR(__xludf.DUMMYFUNCTION("""COMPUTED_VALUE"""),5.02) -> 5.02 | E6: =IFERROR(__xludf.DUMMYFUNCTION("""COMPUTED_VALUE"""),45187.73611111111) -> 45187.736 | F6: =IFERROR(__xludf.DUMMYFUNCTION("""COMPUTED_VALUE"""),93.35) -> 93.35 | G6: =IFERROR(__xludf.DUMMYFUNCTION("""COMPUTED_VALUE"""),45187.726388888885) -> 45187.726 | H6: =IFERROR(__xludf.DUMMYFUNCTION("""COMPUTED_VALUE"""),5.02) -> 5.02 | I6: =IFERROR(__xludf.DUMMYFUNCTION("""COMPUTED_VALUE"""),45187.726388888885) -> 45187.726 | J6: =IFERROR(__xludf.DUMMYFUNCTION("""COMPUTED_VALUE"""),5.01) -> 5.01 | K6: =IFERROR(__xludf.DUMMYFUNCTION("""COMPUTED_VALUE"""),45187.73611111111) -> 45187.736 | L6: =IFERROR(__xludf.DUMMYFUNCTION("""COMPUTED_VALUE"""),93.65) -> 93.65 | M6: =IFERROR(__xludf.DUMMYFUNCTION("""COMPUTED_VALUE"""),45187.726388888885) -> 45187.726 | N6: =IFERROR(__xludf.DUMMYFUNCTION("""COMPUTED_VALUE"""),5.0) -> 5 | O6: =IFERROR(__xludf.DUMMYFUNCTION("""COMPUTED_VALUE"""),45187.6875) -> 45187.688 | P6: =IFERROR(__xludf.DUMMYFUNCTION("""COMPUTED_VALUE"""),466.14) -> 466.14 | Q6: =IFERROR(__xludf.DUMMYFUNCTION("""COMPUTED_VALUE"""),45187.66666666667) -> 45187.667 | R6: =IFERROR(__xludf.DUMMYFUNCTION("""COMPUTED_VALUE"""),22.08) -> 22.08 | S6: =IFERROR(__xludf.DUMMYFUNCTION("""COMPUTED_VALUE"""),45187.6875) -> 45187.688 | T6: =IFERROR(__xludf.DUMMYFUNCTION("""COMPUTED_VALUE"""),5.96) -> 5.96 | U6: =IFERROR(__xludf.DUMMYFUNCTION("""COMPUTED_VALUE"""),45185.99861111111) -> 45185.999 | V6: =IFERROR(__xludf.DUMMYFUNCTION("""COMPUTED_VALUE"""),1.0672) -> 1.0672
A7: =IFERROR(__xludf.DUMMYFUNCTION("""COMPUTED_VALUE"""),45188.73611111111) -> 45188.736 | B7: =IFERROR(__xludf.DUMMYFUNCTION("""COMPUTED_VALUE"""),92.79) -> 92.79 | C7: =IFERROR(__xludf.DUMMYFUNCTION("""COMPUTED_VALUE"""),45188.726388888885) -> 45188.726 | D7: =IFERROR(__xludf.DUMMYFUNCTION("""COMPUTED_VALUE"""),5.01) -> 5.01 | E7: =IFERROR(__xludf.DUMMYFUNCTION("""COMPUTED_VALUE"""),45188.73611111111) -> 45188.736 | F7: =IFERROR(__xludf.DUMMYFUNCTION("""COMPUTED_VALUE"""),93.23) -> 93.23 | G7: =IFERROR(__xludf.DUMMYFUNCTION("""COMPUTED_VALUE"""),45188.726388888885) -> 45188.726 | H7: =IFERROR(__xludf.DUMMYFUNCTION("""COMPUTED_VALUE"""),5.01) -> 5.01 | I7: =IFERROR(__xludf.DUMMYFUNCTION("""COMPUTED_VALUE"""),45188.726388888885) -> 45188.726 | J7: =IFERROR(__xludf.DUMMYFUNCTION("""COMPUTED_VALUE"""),5.01) -> 5.01 | K7: =IFERROR(__xludf.DUMMYFUNCTION("""COMPUTED_VALUE"""),45188.73611111111) -> 45188.736 | L7: =IFERROR(__xludf.DUMMYFUNCTION("""COMPUTED_VALUE"""),93.45) -> 93.45 | M7: =IFERROR(__xludf.DUMMYFUNCTION("""COMPUTED_VALUE"""),45188.726388888885) -> 45188.726 | N7: =IFERROR(__xludf.DUMMYFUNCTION("""COMPUTED_VALUE"""),5.0) -> 5 | O7: =IFERROR(__xludf.DUMMYFUNCTION("""COMPUTED_VALUE"""),45188.6875) -> 45188.688 | P7: =IFERROR(__xludf.DUMMYFUNCTION("""COMPUTED_VALUE"""),462.58) -> 462.58 | Q7: =IFERROR(__xludf.DUMMYFUNCTION("""COMPUTED_VALUE"""),45188.66666666667) -> 45188.667 | R7: =IFERROR(__xludf.DUMMYFUNCTION("""COMPUTED_VALUE"""),22.02) -> 22.02 | S7: =IFERROR(__xludf.DUMMYFUNCTION("""COMPUTED_VALUE"""),45188.6875) -> 45188.688 | T7: =IFERROR(__xludf.DUMMYFUNCTION("""COMPUTED_VALUE"""),5.95) -> 5.95 | U7: =IFERROR(__xludf.DUMMYFUNCTION("""COMPUTED_VALUE"""),45186.99861111111) -> 45186.999 | V7: =IFERROR(__xludf.DUMMYFUNCTION("""COMPUTED_VALUE"""),1.06677) -> 1.06677
A8: =IFERROR(__xludf.DUMMYFUNCTION("""COMPUTED_VALUE"""),45189.73611111111) -> 45189.736 | B8: =IFERROR(__xludf.DUMMYFUNCTION("""COMPUTED_VALUE"""),92.63) -> 92.63 | C8: =IFERROR(__xludf.DUMMYFUNCTION("""COMPUTED_VALUE"""),45189.726388888885) -> 45189.726 | D8: =IFERROR(__xludf.DUMMYFUNCTION("""COMPUTED_VALUE"""),5.01) -> 5.01 | E8: =IFERROR(__xludf.DUMMYFUNCTION("""COMPUTED_VALUE"""),45189.73611111111) -> 45189.736 | F8: =IFERROR(__xludf.DUMMYFUNCTION("""COMPUTED_VALUE"""),93.09) -> 93.09 | G8: =IFERROR(__xludf.DUMMYFUNCTION("""COMPUTED_VALUE"""),45189.726388888885) -> 45189.726 | H8: =IFERROR(__xludf.DUMMYFUNCTION("""COMPUTED_VALUE"""),5.01) -> 5.01 | I8: =IFERROR(__xludf.DUMMYFUNCTION("""COMPUTED_VALUE"""),45189.726388888885) -> 45189.726 | J8: =IFERROR(__xludf.DUMMYFUNCTION("""COMPUTED_VALUE"""),5.01) -> 5.01 | K8: =IFERROR(__xludf.DUMMYFUNCTION("""COMPUTED_VALUE"""),45189.73611111111) -> 45189.736 | L8: =IFERROR(__xludf.DUMMYFUNCTION("""COMPUTED_VALUE"""),93.28) -> 93.28 | M8: =IFERROR(__xludf.DUMMYFUNCTION("""COMPUTED_VALUE"""),45189.726388888885) -> 45189.726 | N8: =IFERROR(__xludf.DUMMYFUNCTION("""COMPUTED_VALUE"""),5.0) -> 5 | O8: =IFERROR(__xludf.DUMMYFUNCTION("""COMPUTED_VALUE"""),45189.6875) -> 45189.688 | P8: =IFERROR(__xludf.DUMMYFUNCTION("""COMPUTED_VALUE"""),465.21) -> 465.21 | Q8: =IFERROR(__xludf.DUMMYFUNCTION("""COMPUTED_VALUE"""),45189.66666666667) -> 45189.667 | R8: =IFERROR(__xludf.DUMMYFUNCTION("""COMPUTED_VALUE"""),22.01) -> 22.01 | S8: =IFERROR(__xludf.DUMMYFUNCTION("""COMPUTED_VALUE"""),45189.6875) -> 45189.688 | T8: =IFERROR(__xludf.DUMMYFUNCTION("""COMPUTED_VALUE"""),5.96) -> 5.96 | U8: =IFERROR(__xludf.DUMMYFUNCTION("""COMPUTED_VALUE"""),45187.99861111111) -> 45187.999 | V8: =IFERROR(__xludf.DUMMYFUNCTION("""COMPUTED_VALUE"""),1.06919) -> 1.06919
