Workbook

Sheet ALL
A1: ASSET | B1: ISIN | C1: LibelléISIN | D1: Quantité | E1: Prix de revient | F1: Place de Cotation | G1: Cours en devise | H1: Cours/VL | I1: Date du cours / VL | J1: Valorisation * | K1: "+/- Values latentes" | L1: Performance** | M1: Poids %
A2: OBLIGATION | B2: IE0000UJ3480 | C2: IS.IBD.DEC.28 T.USD UC.ETF USD IE0000UJ3480 | D2: 1 015 | E2: 98,55 € | F2: Paris | G2: 99,3746 EUR | H2: 993746 | I2: 45361 | J2: 100 865,22 € | K2: 836,97 € | L2: 0,84 % | M2: 4.4466667
A3: OBLIGATION | B3: IE000ZOI8OK5 | C3: ISHARES IBONDS DEC 2027 ¤ CORP IE000ZOI8OK5 | D3: 9 435 | E3: 5,30 € | F3: Frankfurt_ETF_ETP | G3: 5,3822 EUR | H3: 53822 | I3: 45361 | J3: 50 781,06 € | K3: 775,56 € | L3: 1,55 % | M3: 2.24
A4: OBLIGATION | B4: IE000BWITBP9 | C4: ISHRS IBD DEC 26 USD -ACC IE000BWITBP9 | D4: 2 040 | E4: 9794870 | F4: London | G4: 108,07 USD | H4: 9789836 | I4: 45361 | J4: 199 712,66 € | K4: -102,69 € | L4: -0,05 % | M4: 8.8066667
A5: OBLIGATION | B5: IE000GUOATN7 | C5: ISHS IBONDS DEC25 UC.ETF C EUR IE000GUOATN7 | D5: 19 212 | E5: 5205 | F5: Frankfurt_ETF_ETP | G5: 5,2234 EUR | H5: 52234 | I5: 45361 | J5: 100 351,96 € | K5: 353,50 € | L5: 0,35 % | M5: 4.4266667
A6: OBLIGATION | B6: IE000WA6L436 | C6: ISHS IBONDS DEC26 UC.ETF C EUR IE000WA6L436 | D6: 19 665 | E6: 52508 | F6: Paris | G6: 5,313 EUR | H6: 5313 | I6: 45361 | J6: 104 480,15 € | K6: 1 223,17 € | L6: 1,18 % | M6: 4.6066667
A7: OBLIGATION | B7: IE000I1D7D10 | C7: ISHS IBONDS DEC27 UC.ETF C USD IE000I1D7D10 | D7: 1 015 | E7: 98,70 € | F7: Paris | G7: 99,1209 EUR | H7: 991209 | I7: 45361 | J7: 100 607,71 € | K7: 427,21 € | L7: 0,43 % | M7: 4.44
A8: OBLIGATION | B8: IE0008UEVOE0 | C8: ISHS IBONDS DEC28 UC.ETF C EUR IE0008UEVOE0 | D8: 9 375 | E8: 53343 | F8: Paris | G8: 5,432 EUR | H8: 5432 | I8: 45361 | J8: 50 925,00 € | K8: 915,94 € | L8: 1,83 % | M8: 2.2466667
A9: OBLIGATION | B9: LU0115290974 | C9: ODDO BHF EUR.HIG.YLD BD CR-EUR LU0115290974 | D9: 8 319,19 | E9: 30051 | F9: OPC | G9: 30,477 EUR | H9: 30477 | I9: 45332 | J9: 253 543,95 € | K9: 3 543,97 € | L9: 1,42 % | M9: 11.186667
A10: OBLIGATION | B10: DE000A2QBG39 | C10: ODDO BHF MONEY MARKET CN-EUR DE000A2QBG39 | D10: 518363 | E10: 1 041,74000 € | F10: OPC | G10: 1048,23 EUR | H10: 1048,23 € | I10: 45332 | J10: 543 363,65 € | K10: 3 364,18 € | L10: 0,62 % | M10: 23.966667
A11: EQUITY | B11: IE00B5BMR087 | C11: ISHARES CORE S&P 500 UCITS ETF IE00B5BMR087 | D11: 1400 | E11: 53444571 | F11: Frankfurt_ETF_ETP | G11: 545,48 EUR | H11: 545,48 € | I11: 45361 | J11: 763 672,00 € | K11: 15448,00 € | L11: 2,06 % | M11: 33.333333

Sheet VIX HISTORIQUE
B1: PRODUCT | D1: DATE | E1: 2018 | F1: 6 | G1: 8 | I1: TYPE | J1: DAILY
B2: S&P
B3: .INX | D3: VIX | F3: VIX3M | H3: VIX6M | J3: VIX1Y
A4: =IFERROR(__xludf.DUMMYFUNCTION("GOOGLEFINANCE(B$3, ""price"", DATE($E$1, $F$1, $G$1), TODAY(), $J$1)"),"Loading...") -> Loading... | C4: =IFERROR(__xludf.DUMMYFUNCTION("GOOGLEFINANCE(D$3, ""price"", DATE($E$1, $F$1, $G$1), TODAY(), $J$1)"),"Loading...") -> Loading... | E4: =IFERROR(__xludf.DUMMYFUNCTION("GOOGLEFINANCE(F$3, ""price"", DATE($E$1, $F$1, $G$1), TODAY(), $J$1)"),"Loading...") -> Loading... | G4: =IFERROR(__xludf.DUMMYFUNCTION("GOOGLEFINANCE(H$3, ""price"", DATE($E$1, $F$1, $G$1), TODAY(), $J$1)"),"Loading...") -> Loading... | I4: =IFERROR(__xludf.DUMMYFUNCTION("GOOGLEFINANCE(J$3, ""price"", DATE($E$1, $F$1, $G$1), TODAY(), $J$1)"),"Loading...") -> Loading...
L8: aa
L9: =58000*1.202 -> 69716
L11: =6*1500+6*5000 -> 39000
L12: =12*1800 -> 21600

Sheet VIX HISTORIQUE OPEN
B1: PRODUCT | D1: DATE | E1: 2018 | F1: 6 | G1: 8 | I1: TYPE | J1: DAILY
B2: S&P
B3: .INX | D3: VIX | F3: VIX3M | H3: VIX6M | J3: VIX1Y
A4: =IFERROR(__xludf.DUMMYFUNCTION("GOOGLEFINANCE(B$3, ""open"", DATE($E$1, $F$1, $G$1), TODAY(), $J$1)"),"Loading...") -> Loading... | C4: =IFERROR(__xludf.DUMMYFUNCTION("GOOGLEFINANCE(D$3, ""open"", DATE($E$1, $F$1, $G$1), TODAY(), $J$1)"),"Loading...") -> Loading... | E4: =IFERROR(__xludf.DUMMYFUNCTION("GOOGLEFINANCE(F$3, ""open"", DATE($E$1, $F$1, $G$1), TODAY(), $J$1)"),"Loading...") -> Loading... | G4: =IFERROR(__xludf.DUMMYFUNCTION("GOOGLEFINANCE(H$3, ""open"", DATE($E$1, $F$1, $G$1), TODAY(), $J$1)"),"Loading...") -> Loading... | I4: =IFERROR(__xludf.DUMMYFUNCTION("GOOGLEFINANCE(J$3, ""open"", DATE($E$1, $F$1, $G$1), TODAY(), $J$1)"),"Loading...") -> Loading...

Sheet VIXHISTORIQUEMODEL
A1: Date | B1: SPX | C1: VIX | D1: VIX3M | E1: VIX6M | F1: VIX1Y
A2: ='VIX HISTORIQUE'!A5 | B2: ='VIX HISTORIQUE'!B5 | C2: ='VIX HISTORIQUE'!D5 | D2: ='VIX HISTORIQUE'!F5 | E2: ='VIX HISTORIQUE'!H5 | F2: ='VIX HISTORIQUE'!J5
A3: ='VIX HISTORIQUE'!A6 | B3: ='VIX HISTORIQUE'!B6 | C3: ='VIX HISTORIQUE'!D6 | D3: ='VIX HISTORIQUE'!F6 | E3: ='VIX HISTORIQUE'!H6 | F3: ='VIX HISTORIQUE'!J6
A4: ='VIX HISTORIQUE'!A7 | B4: ='VIX HISTORIQUE'!B7 | C4: ='VIX HISTORIQUE'!D7 | D4: ='VIX HISTORIQUE'!F7 | E4: ='VIX HISTORIQUE'!H7 | F4: ='VIX HISTORIQUE'!J7
A5: ='VIX HISTORIQUE'!A8 | B5: ='VIX HISTORIQUE'!B8 | C5: ='VIX HISTORIQUE'!D8 | D5: ='VIX HISTORIQUE'!F8 | E5: ='VIX HISTORIQUE'!H8 | F5: ='VIX HISTORIQUE'!J8
A6: ='VIX HISTORIQUE'!A9 | B6: ='VIX HISTORIQUE'!B9 | C6: ='VIX HISTORIQUE'!D9 | D6: ='VIX HISTORIQUE'!F9 | E6: ='VIX HISTORIQUE'!H9 | F6: ='VIX HISTORIQUE'!J9
A7: ='VIX HISTORIQUE'!A10 | B7: ='VIX HISTORIQUE'!B10 | C7: ='VIX HISTORIQUE'!D10 | D7: ='VIX HISTORIQUE'!F10 | E7: ='VIX HISTORIQUE'!H10 | F7: ='VIX HISTORIQUE'!J10
A8: ='VIX HISTORIQUE'!A11 | B8: ='VIX HISTORIQUE'!B11 | C8: ='VIX HISTORIQUE'!D11 | D8: ='VIX HISTORIQUE'!F11 | E8: ='VIX HISTORIQUE'!H11 | F8: ='VIX HISTORIQUE'!J11
A9: ='VIX HISTORIQUE'!A12 | B9: ='VIX HISTORIQUE'!B12 | C9: ='VIX HISTORIQUE'!D12 | D9: ='VIX HISTORIQUE'!F12 | E9: ='VIX HISTORIQUE'!H12 | F9: ='VIX HISTORIQUE'!J12
A10: ='VIX HISTORIQUE'!A13 | B10: ='VIX HISTORIQUE'!B13 | C10: ='VIX HISTORIQUE'!D13 | D10: ='VIX HISTORIQUE'!F13 | E10: ='VIX HISTORIQUE'!H13 | F10: ='VIX HISTORIQUE'!J13
A11: ='VIX HISTORIQUE'!A14 | B11: ='VIX HISTORIQUE'!B14 | C11: ='VIX HISTORIQUE'!D14 | D11: ='VIX HISTORIQUE'!F14 | E11: ='VIX HISTORIQUE'!H14 | F11: ='VIX HISTORIQUE'!J14
A12: ='VIX HISTORIQUE'!A15 | B12: ='VIX HISTORIQUE'!B15 | C12: ='VIX HISTORIQUE'!D15 | D12: ='VIX HISTORIQUE'!F15 | E12: ='VIX HISTORIQUE'!H15 | F12: ='VIX HISTORIQUE'!J15
A13: ='VIX HISTORIQUE'!A16 | B13: ='VIX HISTORIQUE'!B16 | C13: ='VIX HISTORIQUE'!D16 | D13: ='VIX HISTORIQUE'!F16 | E13: ='VIX HISTORIQUE'!H16 | F13: ='VIX HISTORIQUE'!J16
... A1340: ='VIX HISTORIQUE'!A1343 | B1340: ='VIX HISTORIQUE'!B1343 | C1340: ='VIX HISTORIQUE'!D1343 | D1340: ='VIX HISTORIQUE'!F1343 | E1340: ='VIX HISTORIQUE'!H1343 | F1340: ='VIX HISTORIQUE'!J1343
A1349: ='VIX HISTORIQUE'!A1344 | B1349: ='VIX HISTORIQUE'!B1344 | C1349: ='VIX HISTORIQUE'!D1344 | D1349: ='VIX HISTORIQUE'!F1344 | E1349: ='VIX HISTORIQUE'!H1344 | F1349: ='VIX HISTORIQUE'!J1344
A1350: ='VIX HISTORIQUE'!A1345 | B1350: ='VIX HISTORIQUE'!B1345 | C1350: ='VIX HISTORIQUE'!D1345 | D1350: ='VIX HISTORIQUE'!F1345 | E1350: ='VIX HISTORIQUE'!H1345 | F1350: ='VIX HISTORIQUE'!J1345
A1351: ='VIX HISTORIQUE'!A1346 | B1351: ='VIX HISTORIQUE'!B1346 | C1351: ='VIX HISTORIQUE'!D1346 | D1351: ='VIX HISTORIQUE'!F1346 | E1351: ='VIX HISTORIQUE'!H1346 | F1351: ='VIX HISTORIQUE'!J1346
A1352: ='VIX HISTORIQUE'!A1347 | B1352: ='VIX HISTORIQUE'!B1347 | C1352: ='VIX HISTORIQUE'!D1347 | D1352: ='VIX HISTORIQUE'!F1347 | E1352: ='VIX HISTORIQUE'!H1347 | F1352: ='VIX HISTORIQUE'!J1347
A1353: ='VIX HISTORIQUE'!A1348 | B1353: ='VIX HISTORIQUE'!B1348 | C1353: ='VIX HISTORIQUE'!D1348 | D1353: ='VIX HISTORIQUE'!F1348 | E1353: ='VIX HISTORIQUE'!H1348 | F1353: ='VIX HISTORIQUE'!J1348
A1354: ='VIX HISTORIQUE'!A1349 | B1354: ='VIX HISTORIQUE'!B1349 | C1354: ='VIX HISTORIQUE'!D1349 | D1354: ='VIX HISTORIQUE'!F1349 | E1354: ='VIX HISTORIQUE'!H1349 | F1354: ='VIX HISTORIQUE'!J1349
A1355: ='VIX HISTORIQUE'!A1350 | B1355: ='VIX HISTORIQUE'!B1350 | C1355: ='VIX HISTORIQUE'!D1350 | D1355: ='VIX HISTORIQUE'!F1350 | E1355: ='VIX HISTORIQUE'!H1350 | F1355: ='VIX HISTORIQUE'!J1350
A1356: ='VIX HISTORIQUE'!A1351 | B1356: ='VIX HISTORIQUE'!B1351 | C1356: ='VIX HISTORIQUE'!D1351 | D1356: ='VIX HISTORIQUE'!F1351 | E1356: ='VIX HISTORIQUE'!H1351 | F1356: ='VIX HISTORIQUE'!J1351
A1357: ='VIX HISTORIQUE'!A1352 | B1357: ='VIX HISTORIQUE'!B1352 | C1357: ='VIX HISTORIQUE'!D1352 | D1357: ='VIX HISTORIQUE'!F1352 | E1357: ='VIX HISTORIQUE'!H1352 | F1357: ='VIX HISTORIQUE'!J1352
A1358: ='VIX HISTORIQUE'!A1353 | B1358: ='VIX HISTORIQUE'!B1353 | C1358: ='VIX HISTORIQUE'!D1353 | D1358: ='VIX HISTORIQUE'!F1353 | E1358: ='VIX HISTORIQUE'!H1353 | F1358: ='VIX HISTORIQUE'!J1353
A1359: ='VIX HISTORIQUE'!A1354 | B1359: ='VIX HISTORIQUE'!B1354 | C1359: ='VIX HISTORIQUE'!D1354 | D1359: ='VIX HISTORIQUE'!F1354 | E1359: ='VIX HISTORIQUE'!H1354 | F1359: ='VIX HISTORIQUE'!J1354
A1360: ='VIX HISTORIQUE'!A1355 | B1360: ='VIX HISTORIQUE'!B1355 | C1360: ='VIX HISTORIQUE'!D1355 | D1360: ='VIX HISTORIQUE'!F1355 | E1360: ='VIX HISTORIQUE'!H1355 | F1360: ='VIX HISTORIQUE'!J1355
... A1602: ='VIX HISTORIQUE'!A1597 | B1602: ='VIX HISTORIQUE'!B1597 | C1602: ='VIX HISTORIQUE'!D1597 | D1602: ='VIX HISTORIQUE'!F1597 | E1602: ='VIX HISTORIQUE'!H1597 | F1602: ='VIX HISTORIQUE'!J1597
A1603: ='VIX HISTORIQUE'!A2119 | B1603: ='VIX HISTORIQUE'!B2119 | C1603: ='VIX HISTORIQUE'!D2119 | D1603: ='VIX HISTORIQUE'!G2119 | E1603: ='VIX HISTORIQUE'!I2119 | F1603: =#REF! -> #REF!
A1604: ='VIX HISTORIQUE'!A2120 | B1604: ='VIX HISTORIQUE'!B2120 | C1604: ='VIX HISTORIQUE'!D2120 | D1604: ='VIX HISTORIQUE'!G2120 | E1604: ='VIX HISTORIQUE'!I2120 | F1604: =#REF! -> #REF!
A1605: ='VIX HISTORIQUE'!A2121 | B1605: ='VIX HISTORIQUE'!B2121 | C1605: ='VIX HISTORIQUE'!D2121 | D1605: ='VIX HISTORIQUE'!G2121 | E1605: ='VIX HISTORIQUE'!I2121 | F1605: =#REF! -> #REF!
A1606: ='VIX HISTORIQUE'!A2122 | B1606: ='VIX HISTORIQUE'!B2122 | C1606: ='VIX HISTORIQUE'!D2122 | D1606: ='VIX HISTORIQUE'!G2122 | E1606: ='VIX HISTORIQUE'!I2122 | F1606: =#REF! -> #REF!
A1607: ='VIX HISTORIQUE'!A2123 | B1607: ='VIX HISTORIQUE'!B2123 | C1607: ='VIX HISTORIQUE'!D2123 | D1607: ='VIX HISTORIQUE'!G2123 | E1607: ='VIX HISTORIQUE'!I2123 | F1607: =#REF! -> #REF!
A1608: ='VIX HISTORIQUE'!A2124 | B1608: ='VIX HISTORIQUE'!B2124 | C1608: ='VIX HISTORIQUE'!D2124 | D1608: ='VIX HISTORIQUE'!G2124 | E1608: ='VIX HISTORIQUE'!I2124 | F1608: =#REF! -> #REF!
A1609: ='VIX HISTORIQUE'!A2125 | B1609: ='VIX HISTORIQUE'!B2125 | C1609: ='VIX HISTORIQUE'!D2125 | D1609: ='VIX HISTORIQUE'!G2125 | E1609: ='VIX HISTORIQUE'!I2125 | F1609: =#REF! -> #REF!
A1610: ='VIX HISTORIQUE'!A2126 | B1610: ='VIX HISTORIQUE'!B2126 | C1610: ='VIX HISTORIQUE'!D2126 | D1610: ='VIX HISTORIQUE'!G2126 | E1610: ='VIX HISTORIQUE'!I2126 | F1610: =#REF! -> #REF!
A1611: ='VIX HISTORIQUE'!A2127 | B1611: ='VIX HISTORIQUE'!B2127 | C1611: ='VIX HISTORIQUE'!D2127 | D1611: ='VIX HISTORIQUE'!G2127 | E1611: ='VIX HISTORIQUE'!I2127 | F1611: =#REF! -> #REF!
A1612: ='VIX HISTORIQUE'!A2128 | B1612: ='VIX HISTORIQUE'!B2128 | C1612: ='VIX HISTORIQUE'!D2128 | D1612: ='VIX HISTORIQUE'!G2128 | E1612: ='VIX HISTORIQUE'!I2128 | F1612: =#REF! -> #REF!
A1613: ='VIX HISTORIQUE'!A2129 | B1613: ='VIX HISTORIQUE'!B2129 | C1613: ='VIX HISTORIQUE'!D2129 | D1613: ='VIX HISTORIQUE'!G2129 | E1613: ='VIX HISTORIQUE'!I2129 | F1613: =#REF! -> #REF!
A1614: ='VIX HISTORIQUE'!A2130 | B1614: ='VIX HISTORIQUE'!B2130 | C1614: ='VIX HISTORIQUE'!D2130 | D1614: ='VIX HISTORIQUE'!G2130 | E1614: ='VIX HISTORIQUE'!I2130 | F1614: =#REF! -> #REF!
... A1624: ='VIX HISTORIQUE'!A2140 | B1624: ='VIX HISTORIQUE'!B2140 | C1624: ='VIX HISTORIQUE'!D2140 | D1624: ='VIX HISTORIQUE'!G2140 | E1624: ='VIX HISTORIQUE'!I2140 | F1624: =#REF! -> #REF!

Sheet Portfolio
A1: ASSET | B1: CURRENCY | C1: GCODE | D1: ISIN | E1: DESCR | F1: MAT | G1: YTM | H1: LibelléISIN | I1: Quantité | J1: Prix de revient | K1: Place de Cotation | L1: Cours en devise | M1: Cours/VL | N1: Date du cours / VL | O1: Valorisation * | P1: "+/- Values latentes" | Q1: Performance** | R1: Poids %
A2: OBLIGATION | B2: EUR | C2: 28ID | D2: IE0000UJ3480 | E2: US CORPORATE, US A 45%, BBB 55% | F2: 45654 | G2: 4.5 | H2: IS.IBD.DEC.28 T.USD UC.ETF USD IE0000UJ3480 | I2: 1 015 | J2: 98,55 € | K2: Paris | L2: 99,3746 EUR | M2: 993746 | N2: 45361 | O2: 100 865,22 € | P2: 836,97 € | Q2: 0,84 % | R2: 9.4964161
A3: OBLIGATION | B3: EUR | C3: IB27 | D3: IE000ZOI8OK5 | E3: EURO CORPORATE , A Or AA 50%, BBB 50% | F3: 45653 | G3: 3.1 | H3: ISHARES IBONDS DEC 2027 ¤ CORP IE000ZOI8OK5 | I3: 9 435 | J3: 5,30 € | K3: Frankfurt_ETF_ETP | L3: 5,3822 EUR | M3: 53822 | N3: 45361 | O3: 50 781,06 € | P3: 775,56 € | Q3: 1,55 % | R3: 4.7838018
A4: OBLIGATION | B4: EUR | C4: 26ID | D4: IE000BWITBP9 | E4: US CORPORATE, A or AA 60%, BBB 40% | F4: 45652 | G4: 4.5 | H4: ISHRS IBD DEC 26 USD -ACC IE000BWITBP9 | I4: 2 040 | J4: 9794870 | K4: London | L4: 108,07 USD | M4: 9789836 | N4: 45361 | O4: 199 712,66 € | P4: -102,69 € | Q4: -0,05 % | R4: 18.807745
A5: OBLIGATION | B5: EUR | C5: IB25 | D5: IE000GUOATN7 | E5: EURO CORPORATE , A Or AA 50%, BBB 50% | F5: 45651 | G5: 3.5 | H5: ISHS IBONDS DEC25 UC.ETF C EUR IE000GUOATN7 | I5: 19 212 | J5: 5205 | K5: Frankfurt_ETF_ETP | L5: 5,2234 EUR | M5: 52234 | N5: 45361 | O5: 100 351,96 € | P5: 353,50 € | Q5: 0,35 % | R5: 9.4537035
A6: OBLIGATION | B6: EUR | C6: CEBE | D6: IE000WA6L436 | E6: EURO CORPORATE , A Or AA 55%, BBB 45% | F6: 45652 | G6: 3.2 | H6: ISHS IBONDS DEC26 UC.ETF C EUR IE000WA6L436 | I6: 19 665 | J6: 52508 | K6: Paris | L6: 5,313 EUR | M6: 5313 | N6: 45361 | O6: 104 480,15 € | P6: 1 223,17 € | Q6: 1,18 % | R6: 9.8381162
A7: OBLIGATION | B7: USD | C7: DI27 | D7: IE000I1D7D10 | E7: US CORPORATE, A Or AA 50%, BBB 50% | F7: 45653 | G7: 4.5 | H7: ISHS IBONDS DEC27 UC.ETF C USD IE000I1D7D10 | I7: 1 015 | J7: 98,70 € | K7: Paris | L7: 99,1209 EUR | M7: 991209 | N7: 45361 | O7: 100 607,71 € | P7: 427,21 € | Q7: 0,43 % | R7: 9.4821786
A8: OBLIGATION | B8: USD | C8: IVOA | D8: IE0008UEVOE0 | E8: EURO CORPORATE , A Or AA 50%, BBB 50% | F8: 45654 | G8: 3.2 | H8: ISHS IBONDS DEC28 UC.ETF C EUR IE0008UEVOE0 | I8: 9 375 | J8: 53343 | K8: Paris | L8: 5,432 EUR | M8: 5432 | N8: 45361 | O8: 50 925,00 € | P8: 915,94 € | Q8: 1,83 % | R8: 4.7980393
A9: EQUITY | B9: USD | C9: CSPX | D9: IE00B5BMR087 | E9: S&P ETF | H9: ISHARES CORE S&P 500 UCITS ETF IE00B5BMR087 | I9: 1400 | J9: 53444571 | K9: Frankfurt_ETF_ETP | L9: 545,48 EUR | M9: 545,48 € | N9: 45361 | O9: 763 672,00 € | P9: 15448,00 € | Q9: 2,06 % | R9: 33.333333
A10: OBLIGATION | B10: USD | C10: IHYA | D10: IE00BYXYYL56 | E10: BB 45, B 38, CCC and below 17 | F10: 3.6 YEAR | G10: 6.85
A11: OBLIGATION | B11: USD | C11: ID30 | D11: IE0008TDJ461 | E11: US CORPORATE, A or AA 42 BBB 48 | F11: 45656 | G11: 4.6
L15: 1

Sheet Historique
B1: PRODUCT | D1: DATE | E1: 2023 | F1: 9 | G1: 15 | I1: TYPE | J1: DAILY
B2: IE0000UJ3480 | D2: IE000ZOI8OK5 | F2: IE000BWITBP9 | H2: IE000GUOATN7 | J2: IE000WA6L436 | L2: IE000I1D7D10 | N2: IE0008UEVOE0 | P2: IE00B5BMR087 | T2: US46436E3797
B3: 28ID | D3: IB27 | F3: 26ID | H3: IB25 | J3: CEBE | L3: DI27 | N3: IVOA | P3: CSPX | R3: IBHI | T3: IHYA | V3: EURUSD
A4: =IFERROR(__xludf.DUMMYFUNCTION("GOOGLEFINANCE(B$3, ""price"", DATE($E$1, $F$1, $G$1), TODAY(), $J$1)"),"Loading...") -> Loading... | C4: =IFERROR(__xludf.DUMMYFUNCTION("GOOGLEFINANCE(D$3, ""price"", DATE($E$1, $F$1, $G$1), TODAY(), $J$1)"),"Loading...") -> Loading... | E4: =IFERROR(__xludf.DUMMYFUNCTION("GOOGLEFINANCE(F$3, ""price"", DATE($E$1, $F$1, $G$1), TODAY(), $J$1)"),"Loading...") -> Loading... | G4: =IFERROR(__xludf.DUMMYFUNCTION("GOOGLEFINANCE(H$3, ""price"", DATE($E$1, $F$1, $G$1), TODAY(), $J$1)"),"Loading...") -> Loading... | I4: =IFERROR(__xludf.DUMMYFUNCTION("GOOGLEFINANCE(J$3, ""price"", DATE($E$1, $F$1, $G$1), TODAY(), $J$1)"),"Loading...") -> Loading... | K4: =IFERROR(__xludf.DUMMYFUNCTION("GOOGLEFINANCE(L$3, ""price"", DATE($E$1, $F$1, $G$1), TODAY(), $J$1)"),"Loading...") -> Loading... | M4: =IFERROR(__xludf.DUMMYFUNCTION("GOOGLEFINANCE(N$3, ""price"", DATE($E$1, $F$1, $G$1), TODAY(), $J$1)"),"Loading...") -> Loading... | O4: =IFERROR(__xludf.DUMMYFUNCTION("GOOGLEFINANCE(P$3, ""price"", DATE($E$1, $F$1, $G$1), TODAY(), $J$1)"),"Loading...") -> Loading... | Q4: =IFERROR(__xludf.DUMMYFUNCTION("GOOGLEFINANCE(R$3, ""price"", DATE($E$1, $F$1, $G$1), TODAY(), $J$1)"),"Loading...") -> Loading... | S4: =IFERROR(__xludf.DUMMYFUNCTION("GOOGLEFINANCE(T$3, ""price"", DATE($E$1, $F$1, $G$1), TODAY(), $J$1)"),"Loading...") -> Loading... | U4: =IFERROR(__xludf.DUMMYFUNCTION("GOOGLEFINANCE(V$3, ""price"", DATE($E$1, $F$1, $G$1), TODAY(), $J$1)"),"Loading...") -> Loading...

Sheet EQUITY BACKTEST
B1: PRODUCT | D1: DATE | E1: 1999 | F1: 1 | G1: 1 | I1: TYPE | J1: WEEKLY | M1: 0.025
B2: IE00B5BMR087 | G2: IE00B5BMR087 | M2: =1.5^5 -> 7.59375 | R2: PROBABILITY
B3: .INX | C3: TOTAL RETURN | E3: CURRENCY:EURUSD | G3: 3Y ROLL | H3: 5Y ROLL | I3: YIELD | J3: 0.02 | L3: =MEDIAN($G162:$G1348) -> #NUM! | M3: =MEDIAN($H266:$H1345) -> #NUM! | O3: BIN | P3: 3 YEAR | Q3: 5 YEAR | R3: 3 YEAR | S3: 5 YEAR
A4: =IFERROR(__xludf.DUMMYFUNCTION("GOOGLEFINANCE(B$3, ""price"", DATE($E1, $F1, $G1), TODAY(), $J$1)"),"Loading...") -> Loading... | D4: =IFERROR(__xludf.DUMMYFUNCTION("GOOGLEFINANCE(E$3, ""price"", DATE($E1, $F1, $G1), TODAY(), $J$1)"),"Loading...") -> Loading... | F4: COMPOSITE | I4: RETURN | J4: =B526/B5-1 -> #DIV/0! | K4: =C526/C5-1 -> #DIV/0! | O4: -60 | P4: {=FREQUENCY(G162:G1348, $O$4:$O$28)} -> 0 | Q4: =IFERROR(__xludf.DUMMYFUNCTION("FREQUENCY(FILTER(H6:H10000, H6:H10000<>0, H6:H10000<>""""), $O$4:$O$28)"),"#N/A") -> #N/A | R4: =100*P4/P$30 -> #DIV/0! | S4: =100*Q4/Q$30 -> #N/A
C5: =B5 | F5: 100 | O5: =O4+10 -> -50 | P5: 0 | R5: =100*P5/P$30 -> #DIV/0! | S5: =100*Q5/Q$30 -> #DIV/0! | T5: =R5+R4 -> #DIV/0! | U5: =S5+S4 -> #DIV/0! | V5: =100-T5 -> #DIV/0! | W5: =100-U5 -> #DIV/0!
C6: =IF(ISBLANK(B6), "", C5 * (1 + (B6 - B5) / B5 + $J$3 / 52)) | F6: =IF(OR(ISBLANK(B6),B6=0),"",F5*((E5/E6)*(C6/C5))) | I6: =AVERAGEIF($H$6:$H$10000, "<>0") -> #DIV/0! | O6: =O5+10 -> -40 | P6: 0 | R6: =100*P6/P$30 -> #DIV/0! | S6: =100*Q6/Q$30 -> #DIV/0! | T6: =R6+T5 -> #DIV/0! | U6: =S6+U5 -> #DIV/0! | V6: =100-T6 -> #DIV/0! | W6: =100-U6 -> #DIV/0!
C7: =IF(ISBLANK(B7), "", C6 * (1 + (B7 - B6) / B6 + $J$3 / 52)) | F7: =IF(OR(ISBLANK(B7),B7=0),"",F6*((E6/E7)*(C7/C6))) | I7: =IFERROR(__xludf.DUMMYFUNCTION("MEDIAN(FILTER(H6:H10000, H6:H10000<>0))"),"#NUM!") -> #NUM! | O7: =O6+10 -> -30 | P7: 0 | R7: =100*P7/P$30 -> #DIV/0! | S7: =100*Q7/Q$30 -> #DIV/0! | T7: =R7+T6 -> #DIV/0! | U7: =S7+U6 -> #DIV/0! | V7: =100-T7 -> #DIV/0! | W7: =100-U7 -> #DIV/0!
C8: =IF(ISBLANK(B8), "", C7 * (1 + (B8 - B7) / B7 + $J$3 / 52)) | F8: =IF(OR(ISBLANK(B8),B8=0),"",F7*((E7/E8)*(C8/C7))) | O8: =O7+10 -> -20 | P8: 0 | R8: =100*P8/P$30 -> #DIV/0! | S8: =100*Q8/Q$30 -> #DIV/0! | T8: =R8+T7 -> #DIV/0! | U8: =S8+U7 -> #DIV/0! | V8: =100-T8 -> #DIV/0! | W8: =100-U8 -> #DIV/0!
C9: =IF(ISBLANK(B9), "", C8 * (1 + (B9 - B8) / B8 + $J$3 / 52)) | F9: =IF(OR(ISBLANK(B9),B9=0),"",F8*((E8/E9)*(C9/C8))) | I9: =1.05^5 -> 1.2762816 | O9: =O8+10 -> -10 | P9: 0 | R9: =100*P9/P$30 -> #DIV/0! | S9: =100*Q9/Q$30 -> #DIV/0! | T9: =R9+T8 -> #DIV/0! | U9: =S9+U8 -> #DIV/0! | V9: =100-T9 -> #DIV/0! | W9: =100-U9 -> #DIV/0!
C10: =IF(ISBLANK(B10), "", C9 * (1 + (B10 - B9) / B9 + $J$3 / 52)) | F10: =IF(OR(ISBLANK(B10),B10=0),"",F9*((E9/E10)*(C10/C9))) | O10: =O9+10 -> 0 | P10: 0 | R10: =100*P10/P$30 -> #DIV/0! | S10: =100*Q10/Q$30 -> #DIV/0! | T10: =R10+T9 -> #DIV/0! | U10: =S10+U9 -> #DIV/0! | V10: =100-T10 -> #DIV/0! | W10: =100-U10 -> #DIV/0!
C11: =IF(ISBLANK(B11), "", C10 * (1 + (B11 - B10) / B10 + $J$3 / 52)) | F11: =IF(OR(ISBLANK(B11),B11=0),"",F10*((E10/E11)*(C11/C10))) | O11: =O10+10 -> 10 | P11: 0 | R11: =100*P11/P$30 -> #DIV/0! | S11: =100*Q11/Q$30 -> #DIV/0! | T11: =R11+T10 -> #DIV/0! | U11: =S11+U10 -> #DIV/0! | V11: =100-T11 -> #DIV/0! | W11: =100-U11 -> #DIV/0!
C12: =IF(ISBLANK(B12), "", C11 * (1 + (B12 - B11) / B11 + $J$3 / 52)) | F12: =IF(OR(ISBLANK(B12),B12=0),"",F11*((E11/E12)*(C12/C11))) | O12: =O11+10 -> 20 | P12: 0 | R12: =100*P12/P$30 -> #DIV/0! | S12: =100*Q12/Q$30 -> #DIV/0! | T12: =R12+T11 -> #DIV/0! | U12: =S12+U11 -> #DIV/0! | V12: =100-T12 -> #DIV/0! | W12: =100-U12 -> #DIV/0!
C13: =IF(ISBLANK(B13), "", C12 * (1 + (B13 - B12) / B12 + $J$3 / 52)) | F13: =IF(OR(ISBLANK(B13),B13=0),"",F12*((E12/E13)*(C13/C12))) | O13: =O12+10 -> 30 | P13: 0 | R13: =100*P13/P$30 -> #DIV/0! | S13: =100*Q13/Q$30 -> #DIV/0! | T13: =R13+T12 -> #DIV/0! | U13: =S13+U12 -> #DIV/0! | V13: =100-T13 -> #DIV/0! | W13: =100-U13 -> #DIV/0!
C14: =IF(ISBLANK(B14), "", C13 * (1 + (B14 - B13) / B13 + $J$3 / 52)) | F14: =IF(OR(ISBLANK(B14),B14=0),"",F13*((E13/E14)*(C14/C13))) | O14: =O13+10 -> 40 | P14: 0 | R14: =100*P14/P$30 -> #DIV/0! | S14: =100*Q14/Q$30 -> #DIV/0! | T14: =R14+T13 -> #DIV/0! | U14: =S14+U13 -> #DIV/0! | V14: =100-T14 -> #DIV/0! | W14: =100-U14 -> #DIV/0!
C15: =IF(ISBLANK(B15), "", C14 * (1 + (B15 - B14) / B14 + $J$3 / 52)) | F15: =IF(OR(ISBLANK(B15),B15=0),"",F14*((E14/E15)*(C15/C14))) | O15: =O14+10 -> 50 | P15: 0 | R15: =100*P15/P$30 -> #DIV/0! | S15: =100*Q15/Q$30 -> #DIV/0! | T15: =R15+T14 -> #DIV/0! | U15: =S15+U14 -> #DIV/0! | V15: =100-T15 -> #DIV/0! | W15: =100-U15 -> #DIV/0!
C16: =IF(ISBLANK(B16), "", C15 * (1 + (B16 - B15) / B15 + $J$3 / 52)) | F16: =IF(OR(ISBLANK(B16),B16=0),"",F15*((E15/E16)*(C16/C15))) | O16: =O15+10 -> 60 | P16: 0 | R16: =100*P16/P$30 -> #DIV/0! | S16: =100*Q16/Q$30 -> #DIV/0! | T16: =R16+T15 -> #DIV/0! | U16: =S16+U15 -> #DIV/0! | V16: =100-T16 -> #DIV/0! | W16: =100-U16 -> #DIV/0!
C17: =IF(ISBLANK(B17), "", C16 * (1 + (B17 - B16) / B16 + $J$3 / 52)) | F17: =IF(OR(ISBLANK(B17),B17=0),"",F16*((E16/E17)*(C17/C16))) | O17: =O16+10 -> 70 | P17: 0 | R17: =100*P17/P$30 -> #DIV/0! | S17: =100*Q17/Q$30 -> #DIV/0! | T17: =R17+T16 -> #DIV/0! | U17: =S17+U16 -> #DIV/0! | V17: =100-T17 -> #DIV/0! | W17: =100-U17 -> #DIV/0!
C18: =IF(ISBLANK(B18), "", C17 * (1 + (B18 - B17) / B17 + $J$3 / 52)) | F18: =IF(OR(ISBLANK(B18),B18=0),"",F17*((E17/E18)*(C18/C17))) | O18: =O17+10 -> 80 | P18: 0 | R18: =100*P18/P$30 -> #DIV/0! | S18: =100*Q18/Q$30 -> #DIV/0! | T18: =R18+T17 -> #DIV/0! | U18: =S18+U17 -> #DIV/0! | V18: =100-T18 -> #DIV/0! | W18: =100-U18 -> #DIV/0!
C19: =IF(ISBLANK(B19), "", C18 * (1 + (B19 - B18) / B18 + $J$3 / 52)) | F19: =IF(OR(ISBLANK(B19),B19=0),"",F18*((E18/E19)*(C19/C18))) | O19: =O18+10 -> 90 | P19: 0 | R19: =100*P19/P$30 -> #DIV/0! | S19: =100*Q19/Q$30 -> #DIV/0! | T19: =R19+T18 -> #DIV/0! | U19: =S19+U18 -> #DIV/0! | V19: =100-T19 -> #DIV/0! | W19: =100-U19 -> #DIV/0!
C20: =IF(ISBLANK(B20), "", C19 * (1 + (B20 - B19) / B19 + $J$3 / 52)) | F20: =IF(OR(ISBLANK(B20),B20=0),"",F19*((E19/E20)*(C20/C19))) | O20: =O19+10 -> 100 | P20: 0 | R20: =100*P20/P$30 -> #DIV/0! | S20: =100*Q20/Q$30 -> #DIV/0! | T20: =R20+T19 -> #DIV/0! | U20: =S20+U19 -> #DIV/0! | V20: =100-T20 -> #DIV/0! | W20: =100-U20 -> #DIV/0!
C21: =IF(ISBLANK(B21), "", C20 * (1 + (B21 - B20) / B20 + $J$3 / 52)) | F21: =IF(OR(ISBLANK(B21),B21=0),"",F20*((E20/E21)*(C21/C20))) | O21: =O20+10 -> 110 | P21: 0 | R21: =100*P21/P$30 -> #DIV/0! | S21: =100*Q21/Q$30 -> #DIV/0! | T21: =R21+T20 -> #DIV/0! | U21: =S21+U20 -> #DIV/0! | V21: =100-T21 -> #DIV/0! | W21: =100-U21 -> #DIV/0!
... C26: =IF(ISBLANK(B26), "", C25 * (1 + (B26 - B25) / B25 + $J$3 / 52)) | F26: =IF(OR(ISBLANK(B26),B26=0),"",F25*((E25/E26)*(C26/C25))) | O26: =O25+10 -> 160 | P26: 0 | R26: =100*P26/P$30 -> #DIV/0! | S26: =100*Q26/Q$30 -> #DIV/0! | T26: =R26+T25 -> #DIV/0! | U26: =S26+U25 -> #DIV/0! | V26: =100-T26 -> #DIV/0! | W26: =100-U26 -> #DIV/0!
C27: =IF(ISBLANK(B27), "", C26 * (1 + (B27 - B26) / B26 + $J$3 / 52)) | F27: =IF(OR(ISBLANK(B27),B27=0),"",F26*((E26/E27)*(C27/C26))) | I27: =1.05^5 -> 1.2762816 | O27: =O26+10 -> 170 | P27: 0 | R27: =100*P27/P$30 -> #DIV/0! | S27: =100*Q27/Q$30 -> #DIV/0! | T27: =R27+T26 -> #DIV/0! | U27: =S27+U26 -> #DIV/0! | V27: =100-T27 -> #DIV/0! | W27: =100-U27 -> #DIV/0!
C28: =IF(ISBLANK(B28), "", C27 * (1 + (B28 - B27) / B27 + $J$3 / 52)) | F28: =IF(OR(ISBLANK(B28),B28=0),"",F27*((E27/E28)*(C28/C27))) | I28: =18+33 -> 51 | O28: =O27+10 -> 180 | P28: 0 | R28: =100*P28/P$30 -> #DIV/0! | S28: =100*Q28/Q$30 -> #DIV/0! | T28: =R28+T27 -> #DIV/0! | U28: =S28+U27 -> #DIV/0! | V28: =100-T28 -> #DIV/0! | W28: =100-U28 -> #DIV/0!
C29: =IF(ISBLANK(B29), "", C28 * (1 + (B29 - B28) / B28 + $J$3 / 52)) | F29: =IF(OR(ISBLANK(B29),B29=0),"",F28*((E28/E29)*(C29/C28))) | P29: 0 | T29: =R29+R28 -> #DIV/0!
C30: =IF(ISBLANK(B30), "", C29 * (1 + (B30 - B29) / B29 + $J$3 / 52)) | F30: =IF(OR(ISBLANK(B30),B30=0),"",F29*((E29/E30)*(C30/C29))) | P30: =SUM(P5:P29) -> 0 | Q30: =SUM(Q5:Q29) -> 0 | S30: =1.05^5 -> 1.2762816 | T30: =2/3*27+1/3*50 -> 34.666667 | U30: =(100+T30)/100 -> 1.3466667
C31: =IF(ISBLANK(B31), "", C30 * (1 + (B31 - B30) / B30 + $J$3 / 52)) | F31: =IF(OR(ISBLANK(B31),B31=0),"",F30*((E30/E31)*(C31/C30))) | T31: =T30^0.2 -> 2.0322747 | U31: =U30^0.2-1 -> 0.061333865
C32: =IF(ISBLANK(B32), "", C31 * (1 + (B32 - B31) / B31 + $J$3 / 52)) | F32: =IF(OR(ISBLANK(B32),B32=0),"",F31*((E31/E32)*(C32/C31))) | U32: =1.07^5 -> 1.4025517
C33: =IF(ISBLANK(B33), "", C32 * (1 + (B33 - B32) / B32 + $J$3 / 52)) | F33: =IF(OR(ISBLANK(B33),B33=0),"",F32*((E32/E33)*(C33/C32)))
C34: =IF(ISBLANK(B34), "", C33 * (1 + (B34 - B33) / B33 + $J$3 / 52)) | F34: =IF(OR(ISBLANK(B34),B34=0),"",F33*((E33/E34)*(C34/C33)))
C35: =IF(ISBLANK(B35), "", C34 * (1 + (B35 - B34) / B34 + $J$3 / 52)) | F35: =IF(OR(ISBLANK(B35),B35=0),"",F34*((E34/E35)*(C35/C34)))
C36: =IF(ISBLANK(B36), "", C35 * (1 + (B36 - B35) / B35 + $J$3 / 52)) | F36: =IF(OR(ISBLANK(B36),B36=0),"",F35*((E35/E36)*(C36/C35)))
C37: =IF(ISBLANK(B37), "", C36 * (1 + (B37 - B36) / B36 + $J$3 / 52)) | F37: =IF(OR(ISBLANK(B37),B37=0),"",F36*((E36/E37)*(C37/C36)))
C38: =IF(ISBLANK(B38), "", C37 * (1 + (B38 - B37) / B37 + $J$3 / 52)) | F38: =IF(OR(ISBLANK(B38),B38=0),"",F37*((E37/E38)*(C38/C37))) | R38: =1.05^5*2/3+1/3*50 -> 17.517521
C39: =IF(ISBLANK(B39), "", C38 * (1 + (B39 - B38) / B38 + $J$3 / 52)) | F39: =IF(OR(ISBLANK(B39),B39=0),"",F38*((E38/E39)*(C39/C38)))
C40: =IF(ISBLANK(B40), "", C39 * (1 + (B40 - B39) / B39 + $J$3 / 52)) | F40: =IF(OR(ISBLANK(B40),B40=0),"",F39*((E39/E40)*(C40/C39))) | R40: =1.05^5 -> 1.2762816 | S40: =2/3*27+1/3*50 -> 34.666667
C41: =IF(ISBLANK(B41), "", C40 * (1 + (B41 - B40) / B40 + $J$3 / 52)) | F41: =IF(OR(ISBLANK(B41),B41=0),"",F40*((E40/E41)*(C41/C40)))
C42: =IF(ISBLANK(B42), "", C41 * (1 + (B42 - B41) / B41 + $J$3 / 52)) | F42: =IF(OR(ISBLANK(B42),B42=0),"",F41*((E41/E42)*(C42/C41)))
C43: =IF(ISBLANK(B43), "", C42 * (1 + (B43 - B42) / B42 + $J$3 / 52)) | F43: =IF(OR(ISBLANK(B43),B43=0),"",F42*((E42/E43)*(C43/C42)))
C44: =IF(ISBLANK(B44), "", C43 * (1 + (B44 - B43) / B43 + $J$3 / 52)) | F44: =IF(OR(ISBLANK(B44),B44=0),"",F43*((E43/E44)*(C44/C43)))
...

Sheet vsSTOXX50E
B1: PRODUCT | C1: DATE | D1: 2010 | E1: 1 | F1: 15 | H1: TYPE | I1: WEEKLY
B3: .INX | D3: CURRENCY:EURUSD | F3: SX5E
A4: =IFERROR(__xludf.DUMMYFUNCTION("GOOGLEFINANCE(B$3, ""price"", DATE($D1, $E1, $F1), TODAY(), $I$1)"),"Loading...") -> Loading... | C4: =IFERROR(__xludf.DUMMYFUNCTION("GOOGLEFINANCE(D$3, ""price"", DATE($D1, $E1, $F1), TODAY(), $I$1)"),"Loading...") -> Loading... | E4: =IFERROR(__xludf.DUMMYFUNCTION("GOOGLEFINANCE(F$3, ""price"", DATE($D1, $E1, $F1), TODAY(), $I$1)"),"Loading...") -> Loading...

Sheet SX5E vs INVERSE ETF
B1: PRODUCT | D1: DATE | E1: 2023 | F1: 10 | G1: 1 | I1: TYPE | J1: WEEKLY
B2: IE00B5BMR087 | G2: IE00B5BMR087
B3: SX5E | D3: BSX
A4: =IFERROR(__xludf.DUMMYFUNCTION("GOOGLEFINANCE(B$3, ""price"", DATE($E1, $F1, $G1), TODAY(), $J$1)"),"Loading...") -> Loading... | C4: =IFERROR(__xludf.DUMMYFUNCTION("GOOGLEFINANCE(D$3, ""price"", DATE($E1, $F1, $G1), TODAY(), $J$1)"),"Loading...") -> Loading... | F4: =B58/B5-1 -> #DIV/0! | H4: =D58/D5-1 -> #DIV/0!

Sheet EQUITYFXCORRELATION
A1: ='EQUITY BACKTEST'!A4 -> Loading... | B1: S&P | C1: USDEUR | D1: CORREL | E1: WEEKLY S&P RETURN | F1: ANNUAL S&P RETURN | G1: ANNUAL FX RETURN | H1: CRASH TEST | I1: EQITY CRASH MOVE | J1: FX CORREL CRASH | K1: TIME TO RECOVERY | L1: -0.05
A2: ='EQUITY BACKTEST'!A5 | B2: ='EQUITY BACKTEST'!B5 | C2: =1/'EQUITY BACKTEST'!E5 -> #DIV/0! | I2: =IF($H2="Crash",100*E2,NA()) -> #N/A | J2: =IF($H2="Crash",100*D2,NA()) -> #N/A | K2: {=IF(H2="Crash",MATCH(TRUE, B3:B100 >= B2, 0),"")} | N2: =MEDIAN(K2:K1000) -> #NUM!
A3: ='EQUITY BACKTEST'!A6 | B3: ='EQUITY BACKTEST'!B6 | C3: =1/'EQUITY BACKTEST'!E6 -> #DIV/0! | E3: =IF(A3<>"", (B3 - B2) / B2, "") | H3: =IF(E3 < $L$1, "Crash", "") | I3: =IF($H3="Crash",100*E3,NA()) -> #N/A | J3: =IF($H3="Crash",100*D3,NA()) -> #N/A | K3: {=IF(H3="Crash",MATCH(TRUE, B4:B101 >= B2, 0),"")} | L3: =AVERAGEIF($I$6:$I$10000, "<>") -> #N/A | N3: =MAX(K2:K1000) -> 0
A4: ='EQUITY BACKTEST'!A7 | B4: ='EQUITY BACKTEST'!B7 | C4: =1/'EQUITY BACKTEST'!E7 -> #DIV/0! | E4: =IF(A4<>"", (B4 - B3) / B3, "") | H4: =IF(E4 < $L$1, "Crash", "") | I4: =IF($H4="Crash",100*E4,NA()) -> #N/A | J4: =IF($H4="Crash",100*D4,NA()) -> #N/A | K4: {=IF(H4="Crash",MATCH(TRUE, B5:B102 >= B3, 0),"")}
A5: ='EQUITY BACKTEST'!A8 | B5: ='EQUITY BACKTEST'!B8 | C5: =1/'EQUITY BACKTEST'!E8 -> #DIV/0! | E5: =IF(A5<>"", (B5 - B4) / B4, "") | H5: =IF(E5 < $L$1, "Crash", "") | I5: =IF($H5="Crash",100*E5,NA()) -> #N/A | J5: =IF($H5="Crash",100*D5,NA()) -> #N/A | K5: {=IF(H5="Crash",MATCH(TRUE, B6:B103 >= B4, 0),"")}
A6: ='EQUITY BACKTEST'!A9 | B6: ='EQUITY BACKTEST'!B9 | C6: =1/'EQUITY BACKTEST'!E9 -> #DIV/0! | E6: =IF(A6<>"", (B6 - B5) / B5, "") | H6: =IF(E6 < $L$1, "Crash", "") | I6: =IF($H6="Crash",100*E6,NA()) -> #N/A | J6: =IF($H6="Crash",100*D6,NA()) -> #N/A | K6: {=IF(H6="Crash",MATCH(TRUE, B7:B104 >= B5, 0),"")}
A7: ='EQUITY BACKTEST'!A10 | B7: ='EQUITY BACKTEST'!B10 | C7: =1/'EQUITY BACKTEST'!E10 -> #DIV/0! | E7: =IF(A7<>"", (B7 - B6) / B6, "") | H7: =IF(E7 < $L$1, "Crash", "") | I7: =IF($H7="Crash",100*E7,NA()) -> #N/A | J7: =IF($H7="Crash",100*D7,NA()) -> #N/A | K7: {=IF(H7="Crash",MATCH(TRUE, B8:B105 >= B6, 0),"")}
A8: ='EQUITY BACKTEST'!A11 | B8: ='EQUITY BACKTEST'!B11 | C8: =1/'EQUITY BACKTEST'!E11 -> #DIV/0! | E8: =IF(A8<>"", (B8 - B7) / B7, "") | H8: =IF(E8 < $L$1, "Crash", "") | I8: =IF($H8="Crash",100*E8,NA()) -> #N/A | J8: =IF($H8="Crash",100*D8,NA()) -> #N/A | K8: {=IF(H8="Crash",MATCH(TRUE, B9:B106 >= B7, 0),"")}
A9: ='EQUITY BACKTEST'!A12 | B9: ='EQUITY BACKTEST'!B12 | C9: =1/'EQUITY BACKTEST'!E12 -> #DIV/0! | E9: =IF(A9<>"", (B9 - B8) / B8, "") | H9: =IF(E9 < $L$1, "Crash", "") | I9: =IF($H9="Crash",100*E9,NA()) -> #N/A | J9: =IF($H9="Crash",100*D9,NA()) -> #N/A | K9: {=IF(H9="Crash",MATCH(TRUE, B10:B107 >= B8, 0),"")}
A10: ='EQUITY BACKTEST'!A13 | B10: ='EQUITY BACKTEST'!B13 | C10: =1/'EQUITY BACKTEST'!E13 -> #DIV/0! | E10: =IF(A10<>"", (B10 - B9) / B9, "") | H10: =IF(E10 < $L$1, "Crash", "") | I10: =IF($H10="Crash",100*E10,NA()) -> #N/A | J10: =IF($H10="Crash",100*D10,NA()) -> #N/A | K10: {=IF(H10="Crash",MATCH(TRUE, B11:B108 >= B9, 0),"")}
A11: ='EQUITY BACKTEST'!A14 | B11: ='EQUITY BACKTEST'!B14 | C11: =1/'EQUITY BACKTEST'!E14 -> #DIV/0! | E11: =IF(A11<>"", (B11 - B10) / B10, "") | H11: =IF(E11 < $L$1, "Crash", "") | I11: =IF($H11="Crash",100*E11,NA()) -> #N/A | J11: =IF($H11="Crash",100*D11,NA()) -> #N/A | K11: {=IF(H11="Crash",MATCH(TRUE, B12:B109 >= B10, 0),"")}
A12: ='EQUITY BACKTEST'!A15 | B12: ='EQUITY BACKTEST'!B15 | C12: =1/'EQUITY BACKTEST'!E15 -> #DIV/0! | E12: =IF(A12<>"", (B12 - B11) / B11, "") | H12: =IF(E12 < $L$1, "Crash", "") | I12: =IF($H12="Crash",100*E12,NA()) -> #N/A | J12: =IF($H12="Crash",100*D12,NA()) -> #N/A | K12: {=IF(H12="Crash",MATCH(TRUE, B13:B110 >= B11, 0),"")}
A13: ='EQUITY BACKTEST'!A16 | B13: ='EQUITY BACKTEST'!B16 | C13: =1/'EQUITY BACKTEST'!E16 -> #DIV/0! | E13: =IF(A13<>"", (B13 - B12) / B12, "") | H13: =IF(E13 < $L$1, "Crash", "") | I13: =IF($H13="Crash",100*E13,NA()) -> #N/A | J13: =IF($H13="Crash",100*D13,NA()) -> #N/A | K13: {=IF(H13="Crash",MATCH(TRUE, B14:B111 >= B12, 0),"")}
A14: ='EQUITY BACKTEST'!A17 | B14: ='EQUITY BACKTEST'!B17 | C14: =1/'EQUITY BACKTEST'!E17 -> #DIV/0! | D14: =CORREL($B2:$B14,$C2:$C14) -> #DIV/0! | E14: =IF(A14<>"", (B14 - B13) / B13, "") | H14: =IF(E14 < $L$1, "Crash", "") | I14: =IF($H14="Crash",100*E14,NA()) -> #N/A | J14: =IF($H14="Crash",100*D14,NA()) -> #N/A | K14: {=IF(H14="Crash",MATCH(TRUE, B15:B112 >= B13, 0),"")}
A15: ='EQUITY BACKTEST'!A18 | B15: ='EQUITY BACKTEST'!B18 | C15: =1/'EQUITY BACKTEST'!E18 -> #DIV/0! | D15: =CORREL($B3:$B15,$C3:$C15) -> #DIV/0! | E15: =IF(A15<>"", (B15 - B14) / B14, "") | H15: =IF(E15 < $L$1, "Crash", "") | I15: =IF($H15="Crash",100*E15,NA()) -> #N/A | J15: =IF($H15="Crash",100*D15,NA()) -> #N/A | K15: {=IF(H15="Crash",MATCH(TRUE, B16:B113 >= B14, 0),"")}
A16: ='EQUITY BACKTEST'!A19 | B16: ='EQUITY BACKTEST'!B19 | C16: =1/'EQUITY BACKTEST'!E19 -> #DIV/0! | D16: =CORREL($B4:$B16,$C4:$C16) -> #DIV/0! | E16: =IF(A16<>"", (B16 - B15) / B15, "") | H16: =IF(E16 < $L$1, "Crash", "") | I16: =IF($H16="Crash",100*E16,NA()) -> #N/A | J16: =IF($H16="Crash",100*D16,NA()) -> #N/A | K16: {=IF(H16="Crash",MATCH(TRUE, B17:B114 >= B15, 0),"")}
A17: ='EQUITY BACKTEST'!A20 | B17: ='EQUITY BACKTEST'!B20 | C17: =1/'EQUITY BACKTEST'!E20 -> #DIV/0! | D17: =CORREL($B5:$B17,$C5:$C17) -> #DIV/0! | E17: =IF(A17<>"", (B17 - B16) / B16, "") | H17: =IF(E17 < $L$1, "Crash", "") | I17: =IF($H17="Crash",100*E17,NA()) -> #N/A | J17: =IF($H17="Crash",100*D17,NA()) -> #N/A | K17: {=IF(H17="Crash",MATCH(TRUE, B18:B115 >= B16, 0),"")}
A18: ='EQUITY BACKTEST'!A21 | B18: ='EQUITY BACKTEST'!B21 | C18: =1/'EQUITY BACKTEST'!E21 -> #DIV/0! | D18: =CORREL($B6:$B18,$C6:$C18) -> #DIV/0! | E18: =IF(A18<>"", (B18 - B17) / B17, "") | H18: =IF(E18 < $L$1, "Crash", "") | I18: =IF($H18="Crash",100*E18,NA()) -> #N/A | J18: =IF($H18="Crash",100*D18,NA()) -> #N/A | K18: {=IF(H18="Crash",MATCH(TRUE, B19:B116 >= B17, 0),"")}
A19: ='EQUITY BACKTEST'!A22 | B19: ='EQUITY BACKTEST'!B22 | C19: =1/'EQUITY BACKTEST'!E22 -> #DIV/0! | D19: =CORREL($B7:$B19,$C7:$C19) -> #DIV/0! | E19: =IF(A19<>"", (B19 - B18) / B18, "") | H19: =IF(E19 < $L$1, "Crash", "") | I19: =IF($H19="Crash",100*E19,NA()) -> #N/A | J19: =IF($H19="Crash",100*D19,NA()) -> #N/A | K19: {=IF(H19="Crash",MATCH(TRUE, B20:B117 >= B18, 0),"")}
A20: ='EQUITY BACKTEST'!A23 | B20: ='EQUITY BACKTEST'!B23 | C20: =1/'EQUITY BACKTEST'!E23 -> #DIV/0! | D20: =CORREL($B8:$B20,$C8:$C20) -> #DIV/0! | E20: =IF(A20<>"", (B20 - B19) / B19, "") | H20: =IF(E20 < $L$1, "Crash", "") | I20: =IF($H20="Crash",100*E20,NA()) -> #N/A | J20: =IF($H20="Crash",100*D20,NA()) -> #N/A | K20: {=IF(H20="Crash",MATCH(TRUE, B21:B118 >= B19, 0),"")}
A21: ='EQUITY BACKTEST'!A24 | B21: ='EQUITY BACKTEST'!B24 | C21: =1/'EQUITY BACKTEST'!E24 -> #DIV/0! | D21: =CORREL($B9:$B21,$C9:$C21) -> #DIV/0! | E21: =IF(A21<>"", (B21 - B20) / B20, "") | H21: =IF(E21 < $L$1, "Crash", "") | I21: =IF($H21="Crash",100*E21,NA()) -> #N/A | J21: =IF($H21="Crash",100*D21,NA()) -> #N/A | K21: {=IF(H21="Crash",MATCH(TRUE, B22:B119 >= B20, 0),"")}
A22: ='EQUITY BACKTEST'!A25 | B22: ='EQUITY BACKTEST'!B25 | C22: =1/'EQUITY BACKTEST'!E25 -> #DIV/0! | D22: =CORREL($B10:$B22,$C10:$C22) -> #DIV/0! | E22: =IF(A22<>"", (B22 - B21) / B21, "") | H22: =IF(E22 < $L$1, "Crash", "") | I22: =IF($H22="Crash",100*E22,NA()) -> #N/A | J22: =IF($H22="Crash",100*D22,NA()) -> #N/A | K22: {=IF(H22="Crash",MATCH(TRUE, B23:B120 >= B21, 0),"")}
A23: ='EQUITY BACKTEST'!A26 | B23: ='EQUITY BACKTEST'!B26 | C23: =1/'EQUITY BACKTEST'!E26 -> #DIV/0! | D23: =CORREL($B11:$B23,$C11:$C23) -> #DIV/0! | E23: =IF(A23<>"", (B23 - B22) / B22, "") | H23: =IF(E23 < $L$1, "Crash", "") | I23: =IF($H23="Crash",100*E23,NA()) -> #N/A | J23: =IF($H23="Crash",100*D23,NA()) -> #N/A | K23: {=IF(H23="Crash",MATCH(TRUE, B24:B121 >= B22, 0),"")}
A24: ='EQUITY BACKTEST'!A27 | B24: ='EQUITY BACKTEST'!B27 | C24: =1/'EQUITY BACKTEST'!E27 -> #DIV/0! | D24: =CORREL($B12:$B24,$C12:$C24) -> #DIV/0! | E24: =IF(A24<>"", (B24 - B23) / B23, "") | H24: =IF(E24 < $L$1, "Crash", "") | I24: =IF($H24="Crash",100*E24,NA()) -> #N/A | J24: =IF($H24="Crash",100*D24,NA()) -> #N/A | K24: {=IF(H24="Crash",MATCH(TRUE, B25:B122 >= B23, 0),"")}
A25: ='EQUITY BACKTEST'!A28 | B25: ='EQUITY BACKTEST'!B28 | C25: =1/'EQUITY BACKTEST'!E28 -> #DIV/0! | D25: =CORREL($B13:$B25,$C13:$C25) -> #DIV/0! | E25: =IF(A25<>"", (B25 - B24) / B24, "") | H25: =IF(E25 < $L$1, "Crash", "") | I25: =IF($H25="Crash",100*E25,NA()) -> #N/A | J25: =IF($H25="Crash",100*D25,NA()) -> #N/A | K25: {=IF(H25="Crash",MATCH(TRUE, B26:B123 >= B24, 0),"")}
... A53: ='EQUITY BACKTEST'!A56 | B53: ='EQUITY BACKTEST'!B56 | C53: =1/'EQUITY BACKTEST'!E56 -> #DIV/0! | D53: =CORREL($B41:$B53,$C41:$C53) -> #DIV/0! | E53: =IF(A53<>"", (B53 - B52) / B52, "") | H53: =IF(E53 < $L$1, "Crash", "") | I53: =IF($H53="Crash",100*E53,NA()) -> #N/A | J53: =IF($H53="Crash",100*D53,NA()) -> #N/A | K53: {=IF(H53="Crash",MATCH(TRUE, B54:B151 >= B52, 0),"")}
A54: ='EQUITY BACKTEST'!A57 | B54: ='EQUITY BACKTEST'!B57 | C54: =1/'EQUITY BACKTEST'!E57 -> #DIV/0! | D54: =CORREL($B42:$B54,$C42:$C54) -> #DIV/0! | E54: =IF(A54<>"", (B54 - B53) / B53, "") | F54: =B54/B2-1 -> #DIV/0! | H54: =IF(E54 < $L$1, "Crash", "") | I54: =IF($H54="Crash",100*E54,NA()) -> #N/A | J54: =IF($H54="Crash",100*D54,NA()) -> #N/A | K54: {=IF(H54="Crash",MATCH(TRUE, B55:B152 >= B53, 0),"")}
A55: ='EQUITY BACKTEST'!A58 | B55: ='EQUITY BACKTEST'!B58 | C55: =1/'EQUITY BACKTEST'!E58 -> #DIV/0! | D55: =CORREL($B43:$B55,$C43:$C55) -> #DIV/0! | E55: =IF(A55<>"", (B55 - B54) / B54, "") | F55: =B55/B3-1 -> #DIV/0! | H55: =IF(E55 < $L$1, "Crash", "") | I55: =IF($H55="Crash",100*E55,NA()) -> #N/A | J55: =IF($H55="Crash",100*D55,NA()) -> #N/A | K55: {=IF(H55="Crash",MATCH(TRUE, B56:B153 >= B54, 0),"")}
A56: ='EQUITY BACKTEST'!A59 | B56: ='EQUITY BACKTEST'!B59 | C56: =1/'EQUITY BACKTEST'!E59 -> #DIV/0! | D56: =CORREL($B44:$B56,$C44:$C56) -> #DIV/0! | E56: =IF(A56<>"", (B56 - B55) / B55, "") | F56: =B56/B4-1 -> #DIV/0! | H56: =IF(E56 < $L$1, "Crash", "") | I56: =IF($H56="Crash",100*E56,NA()) -> #N/A | J56: =IF($H56="Crash",100*D56,NA()) -> #N/A | K56: {=IF(H56="Crash",MATCH(TRUE, B57:B154 >= B55, 0),"")}
A57: ='EQUITY BACKTEST'!A60 | B57: ='EQUITY BACKTEST'!B60 | C57: =1/'EQUITY BACKTEST'!E60 -> #DIV/0! | D57: =CORREL($B45:$B57,$C45:$C57) -> #DIV/0! | E57: =IF(A57<>"", (B57 - B56) / B56, "") | F57: =B57/B5-1 -> #DIV/0! | H57: =IF(E57 < $L$1, "Crash", "") | I57: =IF($H57="Crash",100*E57,NA()) -> #N/A | J57: =IF($H57="Crash",100*D57,NA()) -> #N/A | K57: {=IF(H57="Crash",MATCH(TRUE, B58:B155 >= B56, 0),"")}
A58: ='EQUITY BACKTEST'!A61 | B58: ='EQUITY BACKTEST'!B61 | C58: =1/'EQUITY BACKTEST'!E61 -> #DIV/0! | D58: =CORREL($B46:$B58,$C46:$C58) -> #DIV/0! | E58: =IF(A58<>"", (B58 - B57) / B57, "") | F58: =B58/B6-1 -> #DIV/0! | H58: =IF(E58 < $L$1, "Crash", "") | I58: =IF($H58="Crash",100*E58,NA()) -> #N/A | J58: =IF($H58="Crash",100*D58,NA()) -> #N/A | K58: {=IF(H58="Crash",MATCH(TRUE, B59:B156 >= B57, 0),"")}
A59: ='EQUITY BACKTEST'!A62 | B59: ='EQUITY BACKTEST'!B62 | C59: =1/'EQUITY BACKTEST'!E62 -> #DIV/0! | D59: =CORREL($B47:$B59,$C47:$C59) -> #DIV/0! | E59: =IF(A59<>"", (B59 - B58) / B58, "") | F59: =B59/B7-1 -> #DIV/0! | H59: =IF(E59 < $L$1, "Crash", "") | I59: =IF($H59="Crash",100*E59,NA()) -> #N/A | J59: =IF($H59="Crash",100*D59,NA()) -> #N/A | K59: {=IF(H59="Crash",MATCH(TRUE, B60:B157 >= B58, 0),"")}
A60: ='EQUITY BACKTEST'!A63 | B60: ='EQUITY BACKTEST'!B63 | C60: =1/'EQUITY BACKTEST'!E63 -> #DIV/0! | D60: =CORREL($B48:$B60,$C48:$C60) -> #DIV/0! | E60: =IF(A60<>"", (B60 - B59) / B59, "") | F60: =B60/B8-1 -> #DIV/0! | H60: =IF(E60 < $L$1, "Crash", "") | I60: =IF($H60="Crash",100*E60,NA()) -> #N/A | J60: =IF($H60="Crash",100*D60,NA()) -> #N/A | K60: {=IF(H60="Crash",MATCH(TRUE, B61:B158 >= B59, 0),"")}
A61: ='EQUITY BACKTEST'!A64 | B61: ='EQUITY BACKTEST'!B64 | C61: =1/'EQUITY BACKTEST'!E64 -> #DIV/0! | D61: =CORREL($B49:$B61,$C49:$C61) -> #DIV/0! | E61: =IF(A61<>"", (B61 - B60) / B60, "") | F61: =B61/B9-1 -> #DIV/0! | H61: =IF(E61 < $L$1, "Crash", "") | I61: =IF($H61="Crash",100*E61,NA()) -> #N/A | J61: =IF($H61="Crash",100*D61,NA()) -> #N/A | K61: {=IF(H61="Crash",MATCH(TRUE, B62:B159 >= B60, 0),"")}
A62: ='EQUITY BACKTEST'!A65 | B62: ='EQUITY BACKTEST'!B65 | C62: =1/'EQUITY BACKTEST'!E65 -> #DIV/0! | D62: =CORREL($B50:$B62,$C50:$C62) -> #DIV/0! | E62: =IF(A62<>"", (B62 - B61) / B61, "") | F62: =B62/B10-1 -> #DIV/0! | H62: =IF(E62 < $L$1, "Crash", "") | I62: =IF($H62="Crash",100*E62,NA()) -> #N/A | J62: =IF($H62="Crash",100*D62,NA()) -> #N/A | K62: {=IF(H62="Crash",MATCH(TRUE, B63:B160 >= B61, 0),"")}
A63: ='EQUITY BACKTEST'!A66 | B63: ='EQUITY BACKTEST'!B66 | C63: =1/'EQUITY BACKTEST'!E66 -> #DIV/0! | D63: =CORREL($B51:$B63,$C51:$C63) -> #DIV/0! | E63: =IF(A63<>"", (B63 - B62) / B62, "") | F63: =B63/B11-1 -> #DIV/0! | H63: =IF(E63 < $L$1, "Crash", "") | I63: =IF($H63="Crash",100*E63,NA()) -> #N/A | J63: =IF($H63="Crash",100*D63,NA()) -> #N/A | K63: {=IF(H63="Crash",MATCH(TRUE, B64:B161 >= B62, 0),"")}
A64: ='EQUITY BACKTEST'!A67 | B64: ='EQUITY BACKTEST'!B67 | C64: =1/'EQUITY BACKTEST'!E67 -> #DIV/0! | D64: =CORREL($B52:$B64,$C52:$C64) -> #DIV/0! | E64: =IF(A64<>"", (B64 - B63) / B63, "") | F64: =B64/B12-1 -> #DIV/0! | H64: =IF(E64 < $L$1, "Crash", "") | I64: =IF($H64="Crash",100*E64,NA()) -> #N/A | J64: =IF($H64="Crash",100*D64,NA()) -> #N/A | K64: {=IF(H64="Crash",MATCH(TRUE, B65:B162 >= B63, 0),"")}
A65: ='EQUITY BACKTEST'!A68 | B65: ='EQUITY BACKTEST'!B68 | C65: =1/'EQUITY BACKTEST'!E68 -> #DIV/0! | D65: =CORREL($B53:$B65,$C53:$C65) -> #DIV/0! | E65: =IF(A65<>"", (B65 - B64) / B64, "") | F65: =B65/B13-1 -> #DIV/0! | H65: =IF(E65 < $L$1, "Crash", "") | I65: =IF($H65="Crash",100*E65,NA()) -> #N/A | J65: =IF($H65="Crash",100*D65,NA()) -> #N/A | K65: {=IF(H65="Crash",MATCH(TRUE, B66:B163 >= B64, 0),"")}
... A534: ='EQUITY BACKTEST'!A537 | B534: ='EQUITY BACKTEST'!B537 | C534: =1/'EQUITY BACKTEST'!E537 -> #DIV/0! | D534: =CORREL($B522:$B534,$C522:$C534) -> #DIV/0! | E534: =IF(A534<>"", (B534 - B533) / B533, "") | F534: =B534/B482-1 -> #DIV/0! | H534: =IF(E534 < $L$1, "Crash", "") | I534: =IF($H534="Crash",100*E534,NA()) -> #N/A | J534: =IF($H534="Crash",100*D534,NA()) -> #N/A | K534: {=IF(H534="Crash",MATCH(TRUE, B535:B632 >= B533, 0),"")}
A535: ='EQUITY BACKTEST'!A538 | B535: ='EQUITY BACKTEST'!B538 | C535: =1/'EQUITY BACKTEST'!E538 -> #DIV/0! | D535: =CORREL($B523:$B535,$C523:$C535) -> #DIV/0! | E535: =IF(A535<>"", (B535 - B534) / B534, "") | F535: =B535/B483-1 -> #DIV/0! | H535: =IF(E535 < $L$1, "Crash", "") | I535: =IF($H535="Crash",100*E535,NA()) -> #N/A | J535: =IF($H535="Crash",100*D535,NA()) -> #N/A | K535: {=IF(H535="Crash",MATCH(TRUE, B536:B633 >= B534, 0),"")} | L535: =C534/C528-1 -> #DIV/0!
...

Sheet CRASH CORREL ANALYSIS
A1: ='EQUITY BACKTEST'!A4 -> Loading... | B1: S&P | C1: USDEUR | D1: CORREL | E1: WEEKLY S&P RETURN | F1: WEEKLY FX RETURN | G1: ANNUAL FX RETURN | H1: CRASH TEST | I1: CRASH | K1: -0.1
A2: ='EQUITY BACKTEST'!A5 | B2: ='EQUITY BACKTEST'!B5 | C2: =1/'EQUITY BACKTEST'!E5 -> #DIV/0! | D2: =CORREL($B2:$B54,$C2:$C54) -> #DIV/0!
A3: ='EQUITY BACKTEST'!A6 | B3: ='EQUITY BACKTEST'!B6 | C3: =1/'EQUITY BACKTEST'!E6 -> #DIV/0! | D3: =CORREL($B3:$B55,$C3:$C55) -> #DIV/0! | E3: =IF(A3<>"", (B3 - B2) / B2, "") | F3: =IF(B3<>"", (C3 - C2) / C2, "") | H3: =IF(E3 < $K$1, "Crash", "")
A4: ='EQUITY BACKTEST'!A7 | B4: ='EQUITY BACKTEST'!B7 | C4: =1/'EQUITY BACKTEST'!E7 -> #DIV/0! | D4: =CORREL($B4:$B56,$C4:$C56) -> #DIV/0! | E4: =IF(A4<>"", (B4 - B3) / B3, "") | F4: =IF(B4<>"", (C4 - C3) / C3, "") | H4: =IF(E4 < $K$1, "Crash", "")
A5: ='EQUITY BACKTEST'!A8 | B5: ='EQUITY BACKTEST'!B8 | C5: =1/'EQUITY BACKTEST'!E8 -> #DIV/0! | D5: =CORREL($B5:$B57,$C5:$C57) -> #DIV/0! | E5: =IF(A5<>"", (B5 - B4) / B4, "") | F5: =IF(B5<>"", (C5 - C4) / C4, "") | H5: =IF(E5 < $K$1, "Crash", "")
A6: ='EQUITY BACKTEST'!A9 | B6: ='EQUITY BACKTEST'!B9 | C6: =1/'EQUITY BACKTEST'!E9 -> #DIV/0! | D6: =CORREL($B6:$B58,$C6:$C58) -> #DIV/0! | E6: =IF(A6<>"", (B6 - B5) / B5, "") | F6: =IF(B6<>"", (C6 - C5) / C5, "") | H6: =IF(E6 < $K$1, "Crash", "")
A7: ='EQUITY BACKTEST'!A10 | B7: ='EQUITY BACKTEST'!B10 | C7: =1/'EQUITY BACKTEST'!E10 -> #DIV/0! | D7: =CORREL($B7:$B59,$C7:$C59) -> #DIV/0! | E7: =IF(A7<>"", (B7 - B6) / B6, "") | F7: =IF(B7<>"", (C7 - C6) / C6, "") | H7: =IF(E7 < $K$1, "Crash", "") | J7: =IFERROR(__xludf.DUMMYFUNCTION("CORREL(FILTER(E2:E2000, H2:H2000=""Crash""), FILTER(F2:F2000, H2:H2000=""Crash""))"),"#N/A") -> #N/A
A8: ='EQUITY BACKTEST'!A11 | B8: ='EQUITY BACKTEST'!B11 | C8: =1/'EQUITY BACKTEST'!E11 -> #DIV/0! | D8: =CORREL($B8:$B60,$C8:$C60) -> #DIV/0! | E8: =IF(A8<>"", (B8 - B7) / B7, "") | F8: =IF(B8<>"", (C8 - C7) / C7, "") | H8: =IF(E8 < $K$1, "Crash", "")
A9: ='EQUITY BACKTEST'!A12 | B9: ='EQUITY BACKTEST'!B12 | C9: =1/'EQUITY BACKTEST'!E12 -> #DIV/0! | D9: =CORREL($B9:$B61,$C9:$C61) -> #DIV/0! | E9: =IF(A9<>"", (B9 - B8) / B8, "") | F9: =IF(B9<>"", (C9 - C8) / C8, "") | H9: =IF(E9 < $K$1, "Crash", "")
A10: ='EQUITY BACKTEST'!A13 | B10: ='EQUITY BACKTEST'!B13 | C10: =1/'EQUITY BACKTEST'!E13 -> #DIV/0! | D10: =CORREL($B10:$B62,$C10:$C62) -> #DIV/0! | E10: =IF(A10<>"", (B10 - B9) / B9, "") | F10: =IF(B10<>"", (C10 - C9) / C9, "") | H10: =IF(E10 < $K$1, "Crash", "")
A11: ='EQUITY BACKTEST'!A14 | B11: ='EQUITY BACKTEST'!B14 | C11: =1/'EQUITY BACKTEST'!E14 -> #DIV/0! | D11: =CORREL($B11:$B63,$C11:$C63) -> #DIV/0! | E11: =IF(A11<>"", (B11 - B10) / B10, "") | F11: =IF(B11<>"", (C11 - C10) / C10, "") | H11: =IF(E11 < $K$1, "Crash", "")
A12: ='EQUITY BACKTEST'!A15 | B12: ='EQUITY BACKTEST'!B15 | C12: =1/'EQUITY BACKTEST'!E15 -> #DIV/0! | D12: =CORREL($B12:$B64,$C12:$C64) -> #DIV/0! | E12: =IF(A12<>"", (B12 - B11) / B11, "") | F12: =IF(B12<>"", (C12 - C11) / C11, "") | H12: =IF(E12 < $K$1, "Crash", "")
A13: ='EQUITY BACKTEST'!A16 | B13: ='EQUITY BACKTEST'!B16 | C13: =1/'EQUITY BACKTEST'!E16 -> #DIV/0! | D13: =CORREL($B13:$B65,$C13:$C65) -> #DIV/0! | E13: =IF(A13<>"", (B13 - B12) / B12, "") | F13: =IF(B13<>"", (C13 - C12) / C12, "") | H13: =IF(E13 < $K$1, "Crash", "")
A14: ='EQUITY BACKTEST'!A17 | B14: ='EQUITY BACKTEST'!B17 | C14: =1/'EQUITY BACKTEST'!E17 -> #DIV/0! | D14: =CORREL($B14:$B66,$C14:$C66) -> #DIV/0! | E14: =IF(A14<>"", (B14 - B13) / B13, "") | F14: =IF(B14<>"", (C14 - C13) / C13, "") | H14: =IF(E14 < $K$1, "Crash", "")
A15: ='EQUITY BACKTEST'!A18 | B15: ='EQUITY BACKTEST'!B18 | C15: =1/'EQUITY BACKTEST'!E18 -> #DIV/0! | D15: =CORREL($B15:$B67,$C15:$C67) -> #DIV/0! | E15: =IF(A15<>"", (B15 - B14) / B14, "") | F15: =IF(B15<>"", (C15 - C14) / C14, "") | H15: =IF(E15 < $K$1, "Crash", "")
A16: ='EQUITY BACKTEST'!A19 | B16: ='EQUITY BACKTEST'!B19 | C16: =1/'EQUITY BACKTEST'!E19 -> #DIV/0! | D16: =CORREL($B16:$B68,$C16:$C68) -> #DIV/0! | E16: =IF(A16<>"", (B16 - B15) / B15, "") | F16: =IF(B16<>"", (C16 - C15) / C15, "") | H16: =IF(E16 < $K$1, "Crash", "")
A17: ='EQUITY BACKTEST'!A20 | B17: ='EQUITY BACKTEST'!B20 | C17: =1/'EQUITY BACKTEST'!E20 -> #DIV/0! | D17: =CORREL($B17:$B69,$C17:$C69) -> #DIV/0! | E17: =IF(A17<>"", (B17 - B16) / B16, "") | F17: =IF(B17<>"", (C17 - C16) / C16, "") | H17: =IF(E17 < $K$1, "Crash", "")
A18: ='EQUITY BACKTEST'!A21 | B18: ='EQUITY BACKTEST'!B21 | C18: =1/'EQUITY BACKTEST'!E21 -> #DIV/0! | D18: =CORREL($B18:$B70,$C18:$C70) -> #DIV/0! | E18: =IF(A18<>"", (B18 - B17) / B17, "") | F18: =IF(B18<>"", (C18 - C17) / C17, "") | H18: =IF(E18 < $K$1, "Crash", "")
A19: ='EQUITY BACKTEST'!A22 | B19: ='EQUITY BACKTEST'!B22 | C19: =1/'EQUITY BACKTEST'!E22 -> #DIV/0! | D19: =CORREL($B19:$B71,$C19:$C71) -> #DIV/0! | E19: =IF(A19<>"", (B19 - B18) / B18, "") | F19: =IF(B19<>"", (C19 - C18) / C18, "") | H19: =IF(E19 < $K$1, "Crash", "")
... A534: ='EQUITY BACKTEST'!A537 | B534: ='EQUITY BACKTEST'!B537 | C534: =1/'EQUITY BACKTEST'!E537 -> #DIV/0! | D534: =CORREL($B534:$B586,$C534:$C586) -> #DIV/0! | E534: =IF(A534<>"", (B534 - B533) / B533, "") | F534: =IF(B534<>"", (C534 - C533) / C533, "") | H534: =IF(E534 < $K$1, "Crash", "")
A535: ='EQUITY BACKTEST'!A538 | B535: ='EQUITY BACKTEST'!B538 | C535: =1/'EQUITY BACKTEST'!E538 -> #DIV/0! | D535: =CORREL($B535:$B587,$C535:$C587) -> #DIV/0! | E535: =IF(A535<>"", (B535 - B534) / B534, "") | F535: =IF(B535<>"", (C535 - C534) / C534, "") | H535: =IF(E535 < $K$1, "Crash", "") | I535: =B534/B528-1 -> #DIV/0! | K535: =C534/C528-1 -> #DIV/0!
A536: ='EQUITY BACKTEST'!A539 | B536: ='EQUITY BACKTEST'!B539 | C536: =1/'EQUITY BACKTEST'!E539 -> #DIV/0! | D536: =CORREL($B536:$B588,$C536:$C588) -> #DIV/0! | E536: =IF(A536<>"", (B536 - B535) / B535, "") | F536: =IF(B536<>"", (C536 - C535) / C535, "") | H536: =IF(E536 < $K$1, "Crash", "")
A537: ='EQUITY BACKTEST'!A540 | B537: ='EQUITY BACKTEST'!B540 | C537: =1/'EQUITY BACKTEST'!E540 -> #DIV/0! | D537: =CORREL($B537:$B589,$C537:$C589) -> #DIV/0! | E537: =IF(A537<>"", (B537 - B536) / B536, "") | F537: =IF(B537<>"", (C537 - C536) / C536, "") | H537: =IF(E537 < $K$1, "Crash", "")
A538: ='EQUITY BACKTEST'!A541 | B538: ='EQUITY BACKTEST'!B541 | C538: =1/'EQUITY BACKTEST'!E541 -> #DIV/0! | D538: =CORREL($B538:$B590,$C538:$C590) -> #DIV/0! | E538: =IF(A538<>"", (B538 - B537) / B537, "") | F538: =IF(B538<>"", (C538 - C537) / C537, "") | H538: =IF(E538 < $K$1, "Crash", "")
A539: ='EQUITY BACKTEST'!A542 | B539: ='EQUITY BACKTEST'!B542 | C539: =1/'EQUITY BACKTEST'!E542 -> #DIV/0! | D539: =CORREL($B539:$B591,$C539:$C591) -> #DIV/0! | E539: =IF(A539<>"", (B539 - B538) / B538, "") | F539: =IF(B539<>"", (C539 - C538) / C538, "") | H539: =IF(E539 < $K$1, "Crash", "")
A540: ='EQUITY BACKTEST'!A543 | B540: ='EQUITY BACKTEST'!B543 | C540: =1/'EQUITY BACKTEST'!E543 -> #DIV/0! | D540: =CORREL($B540:$B592,$C540:$C592) -> #DIV/0! | E540: =IF(A540<>"", (B540 - B539) / B539, "") | F540: =IF(B540<>"", (C540 - C539) / C539, "") | H540: =IF(E540 < $K$1, "Crash", "")
A541: ='EQUITY BACKTEST'!A544 | B541: ='EQUITY BACKTEST'!B544 | C541: =1/'EQUITY BACKTEST'!E544 -> #DIV/0! | D541: =CORREL($B541:$B593,$C541:$C593) -> #DIV/0! | E541: =IF(A541<>"", (B541 - B540) / B540, "") | F541: =IF(B541<>"", (C541 - C540) / C540, "") | H541: =IF(E541 < $K$1, "Crash", "")
A542: ='EQUITY BACKTEST'!A545 | B542: ='EQUITY BACKTEST'!B545 | C542: =1/'EQUITY BACKTEST'!E545 -> #DIV/0! | D542: =CORREL($B542:$B594,$C542:$C594) -> #DIV/0! | E542: =IF(A542<>"", (B542 - B541) / B541, "") | F542: =IF(B542<>"", (C542 - C541) / C541, "") | H542: =IF(E542 < $K$1, "Crash", "")
A543: ='EQUITY BACKTEST'!A546 | B543: ='EQUITY BACKTEST'!B546 | C543: =1/'EQUITY BACKTEST'!E546 -> #DIV/0! | D543: =CORREL($B543:$B595,$C543:$C595) -> #DIV/0! | E543: =IF(A543<>"", (B543 - B542) / B542, "") | F543: =IF(B543<>"", (C543 - C542) / C542, "") | H543: =IF(E543 < $K$1, "Crash", "")
A544: ='EQUITY BACKTEST'!A547 | B544: ='EQUITY BACKTEST'!B547 | C544: =1/'EQUITY BACKTEST'!E547 -> #DIV/0! | D544: =CORREL($B544:$B596,$C544:$C596) -> #DIV/0! | E544: =IF(A544<>"", (B544 - B543) / B543, "") | F544: =IF(B544<>"", (C544 - C543) / C543, "") | H544: =IF(E544 < $K$1, "Crash", "")
A545: ='EQUITY BACKTEST'!A548 | B545: ='EQUITY BACKTEST'!B548 | C545: =1/'EQUITY BACKTEST'!E548 -> #DIV/0! | D545: =CORREL($B545:$B597,$C545:$C597) -> #DIV/0! | E545: =IF(A545<>"", (B545 - B544) / B544, "") | F545: =IF(B545<>"", (C545 - C544) / C544, "") | H545: =IF(E545 < $K$1, "Crash", "")
A546: ='EQUITY BACKTEST'!A549 | B546: ='EQUITY BACKTEST'!B549 | C546: =1/'EQUITY BACKTEST'!E549 -> #DIV/0! | D546: =CORREL($B546:$B598,$C546:$C598) -> #DIV/0! | E546: =IF(A546<>"", (B546 - B545) / B545, "") | F546: =IF(B546<>"", (C546 - C545) / C545, "") | H546: =IF(E546 < $K$1, "Crash", "")
A547: ='EQUITY BACKTEST'!A550 | B547: ='EQUITY BACKTEST'!B550 | C547: =1/'EQUITY BACKTEST'!E550 -> #DIV/0! | D547: =CORREL($B547:$B599,$C547:$C599) -> #DIV/0! | E547: =IF(A547<>"", (B547 - B546) / B546, "") | F547: =IF(B547<>"", (C547 - C546) / C546, "") | H547: =IF(E547 < $K$1, "Crash", "")
... A1343: ='EQUITY BACKTEST'!A1346 | B1343: ='EQUITY BACKTEST'!B1346 | C1343: =1/'EQUITY BACKTEST'!E1346 -> #DIV/0! | D1343: =CORREL($B1343:$B1395,$C1343:$C1395) -> #DIV/0! | E1343: =IF(A1343<>"", (B1343 - B1342) / B1342, "") | F1343: =IF(B1343<>"", (C1343 - C1342) / C1342, "") | H1343: =IF(E1343 < $K$1, "Crash", "")
A1344: ='EQUITY BACKTEST'!A1347 | B1344: ='EQUITY BACKTEST'!B1347 | C1344: ='EQUITY BACKTEST'!E1347 | E1344: =IF(A1344<>"", (B1344 - B1343) / B1343, "") | F1344: =IF(B1344<>"", (C1344 - C1343) / C1343, "")
A1345: ='EQUITY BACKTEST'!A1348 | B1345: ='EQUITY BACKTEST'!B1348 | C1345: ='EQUITY BACKTEST'!E1348 | E1345: =IF(A1345<>"", (B1345 - B1344) / B1344, "") | F1345: =IF(B1345<>"", (C1345 - C1344) / C1344, "")
A1346: ='EQUITY BACKTEST'!A1349 | B1346: ='EQUITY BACKTEST'!B1349 | C1346: ='EQUITY BACKTEST'!E1349 | E1346: =IF(A1346<>"", (B1346 - B1345) / B1345, "") | F1346: =IF(B1346<>"", (C1346 - C1345) / C1345, "")
A1347: ='EQUITY BACKTEST'!A1350 | B1347: ='EQUITY BACKTEST'!B1350 | C1347: ='EQUITY BACKTEST'!E1350 | E1347: =IF(A1347<>"", (B1347 - B1346) / B1346, "") | F1347: =IF(B1347<>"", (C1347 - C1346) / C1346, "")
A1348: ='EQUITY BACKTEST'!A1351 | B1348: ='EQUITY BACKTEST'!B1351 | C1348: ='EQUITY BACKTEST'!E1351 | E1348: =IF(A1348<>"", (B1348 - B1347) / B1347, "") | F1348: =IF(B1348<>"", (C1348 - C1347) / C1347, "")
A1349: ='EQUITY BACKTEST'!A1352 | B1349: ='EQUITY BACKTEST'!B1352 | C1349: ='EQUITY BACKTEST'!E1352 | E1349: =IF(A1349<>"", (B1349 - B1348) / B1348, "") | F1349: =IF(B1349<>"", (C1349 - C1348) / C1348, "")
...

Sheet EQUITY BACKTEST STRATEGY
B1: PRODUCT | D1: YIELD | E1: 0.023055816 | G1: DATE | H1: 1999 | I1: 1 | J1: 1 | L1: TYPE | M1: WEEKLY | N1: =C526/C6 -> #DIV/0!
B2: IE00B5BMR087 | G2: IE00B5BMR087 | N2: =1.5^10 -> 57.665039 | S2: PROBILITY
B3: .INX | C3: TOTAL RETURN | J3: CURRENCY:EURUSD | K3: =AVERAGE($G162:$G1348) -> #DIV/0! | L3: =AVERAGE($H266:$H1348) -> #DIV/0! | M3: =MEDIAN($G162:$G1348) -> #DIV/0! | N3: =MEDIAN($H266:$H1345) -> #DIV/0! | P3: BIN | Q3: 3 YEAR | R3: 5 YEAR | U3: 3 YEAR | V3: 5 YEAR
A4: =IFERROR(__xludf.DUMMYFUNCTION("GOOGLEFINANCE(B$3, ""price"", DATE(H1, I1, J1), TODAY(), $M$1)"),"Loading...") -> Loading... | D4: =IFERROR(__xludf.DUMMYFUNCTION("GOOGLEFINANCE(J$3, ""price"", DATE(H1, I1, N1), TODAY(), M1)"),"#DIV/0!") -> #DIV/0! | F4: COMPOSITE | G4: 3Y ROLL | H4: 5Y ROLL | I4: FX | J4: 5Y FX PERF | P4: -60 | Q4: {=FREQUENCY(G162:G1348, $P$4:$P$28)} -> #DIV/0! | R4: {=FREQUENCY(H266:H1348, $P$4:$P$28)} -> #DIV/0! | S4: =100*Q4/Q$30 -> #DIV/0! | T4: =100*R4/R$30 -> #DIV/0!
I5: =1/E5 -> #DIV/0! | P5: =P4+10 -> -50 | S5: =100*Q5/Q$30+S4 -> #DIV/0! | T5: =100*R5/R$30+T4 -> #DIV/0!
C6: =$E$1/52*B5+B6 -> 0 | F6: 100 | I6: =1/E6 -> #DIV/0! | P6: =P5+10 -> -40 | S6: =100*Q6/Q$30+S5 -> #DIV/0! | T6: =100*R6/R$30+T5 -> #DIV/0!
C7: =$E$1/52*B6+B7 -> 0 | F7: =F6*((E7/E6)*(C7/C6)) -> #DIV/0! | I7: =1/E7 -> #DIV/0! | P7: =P6+10 -> -30 | S7: =100*Q7/Q$30+S6 -> #DIV/0! | T7: =100*R7/R$30+T6 -> #DIV/0!
C8: =$E$1/52*B7+B8 -> 0 | F8: =F7*((E8/E7)*(C8/C7)) -> #DIV/0! | I8: =1/E8 -> #DIV/0! | P8: =P7+10 -> -20 | S8: =100*Q8/Q$30+S7 -> #DIV/0! | T8: =100*R8/R$30+T7 -> #DIV/0!
C9: =$E$1/52*B8+B9 -> 0 | F9: =F8*((E9/E8)*(C9/C8)) -> #DIV/0! | I9: =1/E9 -> #DIV/0! | P9: =P8+10 -> -10 | S9: =100*Q9/Q$30+S8 -> #DIV/0! | T9: =100*R9/R$30+T8 -> #DIV/0!
C10: =$E$1/52*B9+B10 -> 0 | F10: =F9*((E10/E9)*(C10/C9)) -> #DIV/0! | I10: =1/E10 -> #DIV/0! | P10: =P9+10 -> 0 | S10: =100*Q10/Q$30+S9 -> #DIV/0! | T10: =100*R10/R$30+T9 -> #DIV/0!
C11: =$E$1/52*B10+B11 -> 0 | F11: =F10*((E11/E10)*(C11/C10)) -> #DIV/0! | I11: =1/E11 -> #DIV/0! | P11: =P10+10 -> 10 | S11: =100*Q11/Q$30+S10 -> #DIV/0! | T11: =100*R11/R$30+T10 -> #DIV/0!
C12: =$E$1/52*B11+B12 -> 0 | F12: =F11*((E12/E11)*(C12/C11)) -> #DIV/0! | I12: =1/E12 -> #DIV/0! | P12: =P11+10 -> 20 | S12: =100*Q12/Q$30+S11 -> #DIV/0! | T12: =100*R12/R$30+T11 -> #DIV/0!
C13: =$E$1/52*B12+B13 -> 0 | F13: =F12*((E13/E12)*(C13/C12)) -> #DIV/0! | I13: =1/E13 -> #DIV/0! | P13: =P12+10 -> 30 | S13: =100*Q13/Q$30+S12 -> #DIV/0! | T13: =100*R13/R$30+T12 -> #DIV/0!
C14: =$E$1/52*B13+B14 -> 0 | F14: =F13*((E14/E13)*(C14/C13)) -> #DIV/0! | I14: =1/E14 -> #DIV/0! | P14: =P13+10 -> 40 | S14: =100*Q14/Q$30+S13 -> #DIV/0! | T14: =100*R14/R$30+T13 -> #DIV/0!
C15: =$E$1/52*B14+B15 -> 0 | F15: =F14*((E15/E14)*(C15/C14)) -> #DIV/0! | I15: =1/E15 -> #DIV/0! | P15: =P14+10 -> 50 | S15: =100*Q15/Q$30+S14 -> #DIV/0! | T15: =100*R15/R$30+T14 -> #DIV/0!
C16: =$E$1/52*B15+B16 -> 0 | F16: =F15*((E16/E15)*(C16/C15)) -> #DIV/0! | I16: =1/E16 -> #DIV/0! | P16: =P15+10 -> 60 | S16: =100*Q16/Q$30+S15 -> #DIV/0! | T16: =100*R16/R$30+T15 -> #DIV/0!
C17: =$E$1/52*B16+B17 -> 0 | F17: =F16*((E17/E16)*(C17/C16)) -> #DIV/0! | I17: =1/E17 -> #DIV/0! | P17: =P16+10 -> 70 | S17: =100*Q17/Q$30+S16 -> #DIV/0! | T17: =100*R17/R$30+T16 -> #DIV/0!
C18: =$E$1/52*B17+B18 -> 0 | F18: =F17*((E18/E17)*(C18/C17)) -> #DIV/0! | I18: =1/E18 -> #DIV/0! | P18: =P17+10 -> 80 | S18: =100*Q18/Q$30+S17 -> #DIV/0! | T18: =100*R18/R$30+T17 -> #DIV/0!
... C28: =$E$1/52*B27+B28 -> 0 | F28: =F27*((E28/E27)*(C28/C27)) -> #DIV/0! | I28: =1/E28 -> #DIV/0! | P28: =P27+10 -> 180 | S28: =100*Q28/Q$30+S27 -> #DIV/0! | T28: =100*R28/R$30+T27 -> #DIV/0!
C29: =$E$1/52*B28+B29 -> 0 | F29: =F28*((E29/E28)*(C29/C28)) -> #DIV/0! | I29: =1/E29 -> #DIV/0!
C30: =$E$1/52*B29+B30 -> 0 | F30: =F29*((E30/E29)*(C30/C29)) -> #DIV/0! | I30: =1/E30 -> #DIV/0! | Q30: =SUM(Q5:Q29) -> 0 | R30: =SUM(R5:R29) -> 0 | T30: =1.05^5 -> 1.2762816 | U30: =2/3*27+1/3*50 -> 34.666667 | V30: =(100+U30)/100 -> 1.3466667
C31: =$E$1/52*B30+B31 -> 0 | F31: =F30*((E31/E30)*(C31/C30)) -> #DIV/0! | I31: =1/E31 -> #DIV/0! | U31: =U30^0.2 -> 2.0322747 | V31: =V30^0.2-1 -> 0.061333865
C32: =$E$1/52*B31+B32 -> 0 | F32: =F31*((E32/E31)*(C32/C31)) -> #DIV/0! | I32: =1/E32 -> #DIV/0! | V32: =1.07^5 -> 1.4025517
C33: =$E$1/52*B32+B33 -> 0 | F33: =F32*((E33/E32)*(C33/C32)) -> #DIV/0! | I33: =1/E33 -> #DIV/0!
C34: =$E$1/52*B33+B34 -> 0 | F34: =F33*((E34/E33)*(C34/C33)) -> #DIV/0! | I34: =1/E34 -> #DIV/0!
C35: =$E$1/52*B34+B35 -> 0 | F35: =F34*((E35/E34)*(C35/C34)) -> #DIV/0! | I35: =1/E35 -> #DIV/0!
C36: =$E$1/52*B35+B36 -> 0 | F36: =F35*((E36/E35)*(C36/C35)) -> #DIV/0! | I36: =1/E36 -> #DIV/0!
C37: =$E$1/52*B36+B37 -> 0 | F37: =F36*((E37/E36)*(C37/C36)) -> #DIV/0! | I37: =1/E37 -> #DIV/0!
C38: =$E$1/52*B37+B38 -> 0 | F38: =F37*((E38/E37)*(C38/C37)) -> #DIV/0! | I38: =1/E38 -> #DIV/0!
C39: =$E$1/52*B38+B39 -> 0 | F39: =F38*((E39/E38)*(C39/C38)) -> #DIV/0! | I39: =1/E39 -> #DIV/0!
C40: =$E$1/52*B39+B40 -> 0 | F40: =F39*((E40/E39)*(C40/C39)) -> #DIV/0! | I40: =1/E40 -> #DIV/0!
C41: =$E$1/52*B40+B41 -> 0 | F41: =F40*((E41/E40)*(C41/C40)) -> #DIV/0! | I41: =1/E41 -> #DIV/0!
C42: =$E$1/52*B41+B42 -> 0 | F42: =F41*((E42/E41)*(C42/C41)) -> #DIV/0! | I42: =1/E42 -> #DIV/0!
C43: =$E$1/52*B42+B43 -> 0 | F43: =F42*((E43/E42)*(C43/C42)) -> #DIV/0! | I43: =1/E43 -> #DIV/0!
C44: =$E$1/52*B43+B44 -> 0 | F44: =F43*((E44/E43)*(C44/C43)) -> #DIV/0! | I44: =1/E44 -> #DIV/0!
... C161: =$E$1/52*B160+B161 -> 0 | F161: =F160*((E161/E160)*(C161/C160)) -> #DIV/0! | I161: =1/E161 -> #DIV/0!
C162: =$E$1/52*B161+B162 -> 0 | F162: =F161*((E162/E161)*(C162/C161)) -> #DIV/0! | G162: =100*(F162/F6-1) -> #DIV/0! | I162: =1/E162 -> #DIV/0!
C163: =$E$1/52*B162+B163 -> 0 | F163: =F162*((E163/E162)*(C163/C162)) -> #DIV/0! | G163: =100*(F163/F7-1) -> #DIV/0! | I163: =1/E163 -> #DIV/0!
C164: =$E$1/52*B163+B164 -> 0 | F164: =F163*((E164/E163)*(C164/C163)) -> #DIV/0! | G164: =100*(F164/F8-1) -> #DIV/0! | I164: =1/E164 -> #DIV/0!
C165: =$E$1/52*B164+B165 -> 0 | F165: =F164*((E165/E164)*(C165/C164)) -> #DIV/0! | G165: =100*(F165/F9-1) -> #DIV/0! | I165: =1/E165 -> #DIV/0!
...

Sheet Daily Perf
A1: DATE | B1: IE0000UJ3480 | C1: IE000ZOI8OK5 | D1: IE000BWITBP9 | E1: IE000GUOATN7 | F1: IE000WA6L436 | G1: IE000I1D7D10 | H1: IE0008UEVOE0 | I1: IE00B5BMR087 | J1: PORTFOLIO ALL | L1: PORTFOLIO BOND
A2: 45184.736 | C2: =B2+2 -> 2 | D2: =C2+2 -> 4 | E2: =D2+2 -> 6 | F2: =E2+2 -> 8 | G2: =F2+2 -> 10 | H2: =G2+2 -> 12 | I2: =H2+2 -> 14 | K2: 100 | M2: 100
